Workbook
Name _GoA1: '20.개정 이력'!_GoA1
Name _GoA1: '[1]4-1.CCTA(UPS5)'!_GoA1
Name _GoA1: '30.작성법'!_GoA1
Name _GoA1: '[1]4-1.CCTA(UPS5)'!_GoA1
Name _GoA1: '[1]4-1.CCTA(UPS5)'!_GoA1
Name _GoA1: [0]!_GoA1
Name Capture.Capture: '20.개정 이력'!Capture.Capture
Name Capture.Capture: '[1]4-1.CCTA(UPS5)'!Capture.Capture
Name Capture.Capture: '30.작성법'!Capture.Capture
Name Capture.Capture: '[1]4-1.CCTA(UPS5)'!Capture.Capture
Name Capture.Capture: '[1]4-1.CCTA(UPS5)'!Capture.Capture
Name Capture.Capture: [0]!Capture.Capture
Name LXCPK: '20.개정 이력'!LXCPK
Name LXCPK: '[1]4-1.CCTA(UPS5)'!LXCPK
Name LXCPK: '30.작성법'!LXCPK
Name LXCPK: '[1]4-1.CCTA(UPS5)'!LXCPK
Name LXCPK: '[1]4-1.CCTA(UPS5)'!LXCPK
Name LXCPK: [0]!LXCPK
Name RANDR폭: '20.개정 이력'!RANDR폭
Name RANDR폭: '[1]4-1.CCTA(UPS5)'!RANDR폭
Name RANDR폭: '30.작성법'!RANDR폭
Name RANDR폭: '[1]4-1.CCTA(UPS5)'!RANDR폭
Name RANDR폭: '[1]4-1.CCTA(UPS5)'!RANDR폭
Name RANDR폭: [0]!RANDR폭
Name 切断評価結果: [3]報告書!$M$15
Name 폭CPK: '20.개정 이력'!폭CPK
Name 폭CPK: '[1]4-1.CCTA(UPS5)'!폭CPK
Name 폭CPK: '30.작성법'!폭CPK
Name 폭CPK: '[1]4-1.CCTA(UPS5)'!폭CPK
Name 폭CPK: '[1]4-1.CCTA(UPS5)'!폭CPK
Name 폭CPK: [0]!폭CPK

Sheet 표지
T26: Ver.0.1
R29: 결 재 | V29: 승 인 | AA29: 검 토 | AF29: 작 성

Sheet 1. PC1_AXIS CHECK LIST(CIM1)
A2: 1. PC1_Axis Check List(CIM)
C4: 1. PC Check List | H4: 이 Page의 내용은 MDIK에서 체크 및 결과를 기록 한다. | S4: OK
S5: NG
D6: 1) Main PC Install | S6: SKIP
D7: NO | E7: 구성 | F7: 기기명 | G7: 기타 사항 | H7: 명칭 | I7: 명칭 약어 (최대 8개, - 제외) | M7: 1차 Check | Q7: 2차 Check
M8: 확인 일자 | N8: 결 과 | O8: 사 유 / 내용 | Q8: 확인 일자 | R8: 결 과 | S8: 사 유
D9: 1 | E9: 프로그램 & Option | F9: Antivirus | G9: AhnLab | H9: AhnLab V3 Internet Security 9.0
F10: Windows | G10: Microsoft | H10: Windows10 64Bit
F11: Excel | G11: Microsoft | H11: Office Home & Buseniss 2021
D17: NO | E17: 구성 | F17: 기기명 | G17: 설정 내용 | H17: 용도 명칭 | I17: 명칭 약어 (최대 8개, - 제외) | M17: 1차 Check | Q17: 2차 Check
M18: 확인 일자 | N18: 결 과 | O18: 사 유 / 내용 | Q18: 확인 일자 | R18: 결 과 | S18: 사 유
D19: 1 | E19: PC PORT | F19: CPU Board Lan Card | G19: Port 1 | H19: HUB#1
G20: Port 2 | H20: Host Ethernet Link
G21: Port 3
F22: Melsec Board (Q80BD-J71GP21S-SX) | G22: Port 1
G23: Port 2
F24: Lan Card I350-T4V2 (Intel - 4 PORT) | G24: Port 1 | H24: Accura Power Meter ( UPS1 )
G25: Port 2 | H25: Accura Power Meter ( GPS )
G26: Port 3 | H26: ESD SENSOR ( SCT )
G27: Port 4

Sheet 2. PC2_AXIS CHECK LIST(SCT)
A2: 2. PC2_Axis Check List(SCT)
C4: 1. PC Check List | H4: 이 Page의 내용은 MDIK에서 체크 및 결과를 기록 한다. | R4: OK
R5: NG
D6: 1) Main PC Install | R6: SKIP
D7: NO | E7: 구성 | F7: 기기명 | G7: 기타 사항 | H7: 명칭 | L7: 1차 Check | P7: 2차 Check
L8: 확인 일자 | M8: 결 과 | N8: 사 유 / 내용 | P8: 확인 일자 | Q8: 결 과 | R8: 사 유
D9: 1 | E9: 프로그램 & Option | F9: Antivirus | G9: AhnLab | H9: AhnLab V3 Internet Security 9.0
F10: Windows | G10: Microsoft | H10: Windows10 64Bit
F11: Excel | G11: Microsoft | H11: Office Home & Buseniss 2021
D17: NO | E17: 구성 | F17: 기기명 | G17: 설정 내용 | H17: 용도 명칭 | L17: 1차 Check | P17: 2차 Check
L18: 확인 일자 | M18: 결 과 | N18: 사 유 / 내용 | P18: 확인 일자 | Q18: 결 과 | R18: 사 유
D19: 1 | E19: PC PORT | F19: CPU Board Lan Card | G19: Port 1 | H19: HUB#1
G20: Port 2 | H20: SCT MP3200
G21: Port 3
F22: Lan Card I350-T4V2 (Intel - 4Port) | G22: Port 1 | H22: MCR
G23: Port 2 | H23: SCT ESD SPARE
G24: Port 3 | H24: UPS1 PM SPARE
G25: Port 4 | H25: GPS PM SPARE
F26: Moxa Card | G26: CP-118EL-A / RS232 | H26: 1 CH : Light Controller 2CH [RS232C] | I26: 33
H27: 2 CH : Light Controller 2CH [RS232C] | I27: 34
H28: 3 CH : Light Controller 2CH [RS232C] | I28: 35
H29: 4 CH : | I29: 36
H30: 5 CH : | I30: 37
H31: 6 CH : Dust 01 [RS485] (온도계) | I31: 38
H32: 7 CH : Dust 01 [RS485] (압력계) | I32: 39
H33: 8 CH : Dust 01 [RS485] (기판) | I33: 40
H34: 8 CH :
H35: 9 CH :
H36: 10 CH :
H37: 11 CH :
H38: 12 CH :
H39: 13 CH :
H40: 14 CH :
H41: 15 CH :
H42: 16 CH :
F43: Moxa Card | G43: CP-116E-A / RS232,485 | H43: 1 CH : SMC01 [RS485 2 Wire] | I43: 17
H44: 2 CH : SMC02 [RS485 2 Wire] | I44: 18
H45: 3 CH : SMC03 [RS485 2 Wire] | I45: 19
H46: 4 CH : SMC04 [RS485 2 Wire] | I46: 20
H47: 5 CH : | I47: 21
...

Sheet 2-1.SCT(UPS1)
B2: =[4]표지!F19 -> SDV SISW-OLED2300-4
B5: SERVO_CABLE | C5: 정격전류
B6: UPS1 SERVO AXIS LIST ( SCT ) | Z6: =SUM(Z9:Z54) -> 2.25 | AA6: =SUM(AA9:AA54) -> 2.25 | AB6: =SUM(AB9:AB54) -> 2.25
B7: PROCESS | D7: DR | H7: DT | I7: MOTOR TYPE | J7: AXIS | K7: 설정 | N7: SERVO PACK | O7: MOTOR | P7: MOTOR SUB | Q7: Watt | R7: CONTROL Power [A] | S7: Input Current [A] | T7: 가동율적용 [A] | U7: CB [A] | V7: Cable | X7: ELECTRONIC BOX NO. | Y7: 제어 전원 번호 | Z7: RS | AA7: RT | AB7: ST | AC7: RESISTOR | AD7: 회생저항
K8: S1 | L8: S2 | M8: 회선 | V8: Power | W8: Encoder
A9: RE | D9: DR2106 | G9: SCT Main Glass Transfer1 Y-1 | H9: =E9&F9&" "&G9 -> SCT Main Glass Transfer1 Y-1 | I9: =IF(OR(LEFT(O9,3)="SGL",LEFT(O9,5)="SGMCS"),"LINEAR","Rotary") -> Rotary | J9: =IF(OR(RIGHT($H9,1)="Z",LEFT(RIGHT($H9,2),1)="Z",LEFT(RIGHT($H9,3),1)="Z"),"Z",IF(OR(RIGHT($H9,1)="X",LEFT(RIGHT($H9,2),1)="X",LEFT(RIGHT($H9,3),1)="X"),"X",IF(OR(RIGHT($H9,1)="Y",LEFT(RIGHT($H9,2),1)="Y",LEFT(RIGHT($H9,3),1)="Y"),"Y","T"))) -> Y | K9: =VLOOKUP($D9,[4]회선정보!B:F,3,FALSE) -> 0 | L9: =VLOOKUP($D9,[4]회선정보!B:F,4,FALSE) -> 6 | M9: =VLOOKUP($D9,[4]회선정보!B:F,5,FALSE) -> MP1-1 | N9: SGD7S-120A20A | O9: SGM7G-13A7A21 | P9: =IFERROR(IF($I9="Rotary",LEFT($O9,9),$O9),"") -> SGM7G-13A | Q9: =IF(MID($N8,5,1)<>"W",VLOOKUP(N9,[4]정격용량!$B$3:$K$633,4,FALSE),"X") -> 1500 | R9: =IF(MID($N8,5,1)<>"W",VLOOKUP(N9,[4]정격용량!$B$3:$K$633,3,FALSE),"X") -> 0.25 | S9: =IF(MID($N8,5,1)<>"W",VLOOKUP(N9,[4]정격용량!$B$3:$K$633,6,FALSE),"X") -> 7.3 | T9: =IF(MID($N8,5,1)<>"W",S9*$C$85,"X") -> 2.7613043 | U9: =IF(MID($N8,5,1)<>"W",VLOOKUP(N9,[4]정격용량!$B$3:$K$633,9,FALSE),"X") -> 10 | V9: =IFERROR(IF(J9="Z",VLOOKUP(P9,'[4]SERVO CABLE'!G:AD,8,FALSE),VLOOKUP(P9,'[4]SERVO CABLE'!G:AD,4,FALSE)),"") -> JZSP-UVA122-□-E | W9: =IFERROR(VLOOKUP(P9,'[4]SERVO CABLE'!G:AD,17,FALSE),"") -> JZSP-CVP27-□-E | Y9: 1 | Z9: =IF($Y9=1,$R$9,"") -> 0.25 | AA9: =IF($Y9=2,$R$9,"") | AB9: =IF($Y9=3,$R$9,"") | AC9: =IF(MID($N8,5,1)<>"W",((700*700)/$Q9*1.509)/1000,"X") -> 0.49294 | AD9: =IF($AC9="X","X",IF($AC9<0.1,"X",IF($AC9<0.27,"IRV60",IF($AC9<0.91,"IRV80",IF($AC9<1.1,"IRV100",IF($AC9<1.3,"IRV120",IF($AC9<1.6,"IRV150",IF($AC9<2.2,"IRV200",IF($AC9<2.7,"IRV300",IF($AC9<4.3,"IRV400",IF($AC9<6.8,"IRV500","X"))))))))))) -> IRV80
A10: RE | D10: DR2107 | G10: SCT Main Glass Transfer1 Y-2 | H10: =E10&F10&" "&G10 -> SCT Main Glass Transfer1 Y-2 | I10: =IF(OR(LEFT(O10,3)="SGL",LEFT(O10,5)="SGMCS"),"LINEAR","Rotary") -> Rotary | J10: =IF(OR(RIGHT($H10,1)="Z",LEFT(RIGHT($H10,2),1)="Z",LEFT(RIGHT($H10,3),1)="Z"),"Z",IF(OR(RIGHT($H10,1)="X",LEFT(RIGHT($H10,2),1)="X",LEFT(RIGHT($H10,3),1)="X"),"X",IF(OR(RIGHT($H10,1)="Y",LEFT(RIGHT($H10,2),1)="Y",LEFT(RIGHT($H10,3),1)="Y"),"Y","T"))) -> Y | K10: =VLOOKUP($D10,[4]회선정보!B:F,3,FALSE) -> 0 | L10: =VLOOKUP($D10,[4]회선정보!B:F,4,FALSE) -> 7 | M10: =VLOOKUP($D10,[4]회선정보!B:F,5,FALSE) -> MP1-1 | N10: SGD7S-120A20A | O10: SGM7G-13A7A21 | P10: =IFERROR(IF($I10="Rotary",LEFT($O10,9),$O10),"") -> SGM7G-13A | Q10: =IF(MID($N9,5,1)<>"W",VLOOKUP(N10,[4]정격용량!$B$3:$K$633,4,FALSE),"X") -> 1500 | R10: =IF(MID(N9,5,1)<>"W",VLOOKUP(N10,[4]정격용량!$B$3:$K$633,3,FALSE),"X") -> 0.25 | S10: =IF(MID(N9,5,1)<>"W",VLOOKUP(N10,[4]정격용량!$B$3:$K$633,6,FALSE),"X") -> 7.3 | T10: =IF(MID($N9,5,1)<>"W",S10*$C$85,"X") -> 2.7613043 | U10: =IF(MID($N9,5,1)<>"W",VLOOKUP(N10,[4]정격용량!$B$3:$K$633,9,FALSE),"X") -> 10 | V10: =IFERROR(IF(J10="Z",VLOOKUP(P10,'[4]SERVO CABLE'!G:AD,8,FALSE),VLOOKUP(P10,'[4]SERVO CABLE'!G:AD,4,FALSE)),"") -> JZSP-UVA122-□-E | W10: =IFERROR(VLOOKUP(P10,'[4]SERVO CABLE'!G:AD,17,FALSE),"") -> JZSP-CVP27-□-E | Z10: =IF($Y10=1,$R$9,"") | AA10: =IF($Y10=2,$R$9,"") | AB10: =IF($Y10=3,$R$9,"") | AC10: =IF(MID($N9,5,1)<>"W",((700*700)/$Q10*1.509)/1000,"X") -> 0.49294 | AD10: =IF($AC10="X","X",IF($AC10<0.1,"X",IF($AC10<0.27,"IRV60",IF($AC10<0.91,"IRV80",IF($AC10<1.1,"IRV100",IF($AC10<1.3,"IRV120",IF($AC10<1.6,"IRV150",IF($AC10<2.2,"IRV200",IF($AC10<2.7,"IRV300",IF($AC10<4.3,"IRV400",IF($AC10<6.8,"IRV500","X"))))))))))) -> IRV80
A11: TR | D11: DR2108 | G11: SCT Main Glass Transfer1 X | H11: =E11&F11&" "&G11 -> SCT Main Glass Transfer1 X | I11: =IF(OR(LEFT(O11,3)="SGL",LEFT(O11,5)="SGMCS"),"LINEAR","Rotary") -> Rotary | J11: =IF(OR(RIGHT($H11,1)="Z",LEFT(RIGHT($H11,2),1)="Z",LEFT(RIGHT($H11,3),1)="Z"),"Z",IF(OR(RIGHT($H11,1)="X",LEFT(RIGHT($H11,2),1)="X",LEFT(RIGHT($H11,3),1)="X"),"X",IF(OR(RIGHT($H11,1)="Y",LEFT(RIGHT($H11,2),1)="Y",LEFT(RIGHT($H11,3),1)="Y"),"Y","T"))) -> X | K11: =VLOOKUP($D11,[4]회선정보!B:F,3,FALSE) -> 0 | L11: =VLOOKUP($D11,[4]회선정보!B:F,4,FALSE) -> 8 | M11: =VLOOKUP($D11,[4]회선정보!B:F,5,FALSE) -> MP1-1 | N11: SGD7S-2R8A20A | O11: SGM7J-04A7A21 | P11: =IFERROR(IF($I11="Rotary",LEFT($O11,9),$O11),"") -> SGM7J-04A | Q11: =IF(MID($N10,5,1)<>"W",VLOOKUP(N11,[4]정격용량!$B$3:$K$633,4,FALSE),"X") -> 400 | R11: =IF(MID(N10,5,1)<>"W",VLOOKUP(N11,[4]정격용량!$B$3:$K$633,3,FALSE),"X") -> 0.2 | S11: =IF(MID(N10,5,1)<>"W",VLOOKUP(N11,[4]정격용량!$B$3:$K$633,6,FALSE),"X") -> 2.5 | T11: =IF(MID($N10,5,1)<>"W",S11*$C$85,"X") -> 0.94565217 | U11: =IF(MID($N10,5,1)<>"W",VLOOKUP(N11,[4]정격용량!$B$3:$K$633,9,FALSE),"X") -> 3 | V11: =IFERROR(IF(J11="Z",VLOOKUP(P11,'[4]SERVO CABLE'!G:AD,8,FALSE),VLOOKUP(P11,'[4]SERVO CABLE'!G:AD,4,FALSE)),"") -> JZSP-C7M22F-□-E | W11: =IFERROR(VLOOKUP(P11,'[4]SERVO CABLE'!G:AD,17,FALSE),"") -> JZSP-C7PA2D-□-E | Y11: 2 | Z11: =IF($Y11=1,$R$9,"") | AA11: =IF($Y11=2,$R$9,"") -> 0.25 | AB11: =IF($Y11=3,$R$9,"") | AC11: =IF(MID($N10,5,1)<>"W",((700*700)/$Q11*1.509)/1000,"X") -> 1.848525 | AD11: =IF($AC11="X","X",IF($AC11<0.1,"X",IF($AC11<0.27,"IRV60",IF($AC11<0.91,"IRV80",IF($AC11<1.1,"IRV100",IF($AC11<1.3,"IRV120",IF($AC11<1.6,"IRV150",IF($AC11<2.2,"IRV200",IF($AC11<2.7,"IRV300",IF($AC11<4.3,"IRV400",IF($AC11<6.8,"IRV500","X"))))))))))) -> IRV200
A12: TR | D12: DR2109 | G12: SCT Main Glass Transfer1 Z-1 | H12: =E12&F12&" "&G12 -> SCT Main Glass Transfer1 Z-1 | I12: =IF(OR(LEFT(O12,3)="SGL",LEFT(O12,5)="SGMCS"),"LINEAR","Rotary") -> Rotary | J12: =IF(OR(RIGHT($H12,1)="Z",LEFT(RIGHT($H12,2),1)="Z",LEFT(RIGHT($H12,3),1)="Z"),"Z",IF(OR(RIGHT($H12,1)="X",LEFT(RIGHT($H12,2),1)="X",LEFT(RIGHT($H12,3),1)="X"),"X",IF(OR(RIGHT($H12,1)="Y",LEFT(RIGHT($H12,2),1)="Y",LEFT(RIGHT($H12,3),1)="Y"),"Y","T"))) -> Z | K12: =VLOOKUP($D12,[4]회선정보!B:F,3,FALSE) -> 0 | L12: =VLOOKUP($D12,[4]회선정보!B:F,4,FALSE) -> 9 | M12: =VLOOKUP($D12,[4]회선정보!B:F,5,FALSE) -> MP1-1 | N12: SGD7W-5R5A20A | O12: SGM7J-08A7A2C | P12: =IFERROR(IF($I12="Rotary",LEFT($O12,9),$O12),"") -> SGM7J-08A | Q12: =IF(MID($N11,5,1)<>"W",VLOOKUP(N12,[4]정격용량!$B$3:$K$633,4,FALSE),"X") -> 1500 | R12: =IF(MID(N11,5,1)<>"W",VLOOKUP(N12,[4]정격용량!$B$3:$K$633,3,FALSE),"X") -> 0.3 | S12: =IF(MID(N11,5,1)<>"W",VLOOKUP(N12,[4]정격용량!$B$3:$K$633,6,FALSE),"X") -> 7.8 | T12: =IF(MID($N11,5,1)<>"W",S12*$C$85,"X") -> 2.9504348 | U12: =IF(MID($N11,5,1)<>"W",VLOOKUP(N12,[4]정격용량!$B$3:$K$633,9,FALSE),"X") -> 10 | V12: =IFERROR(IF(J12="Z",VLOOKUP(P12,'[4]SERVO CABLE'!G:AD,8,FALSE),VLOOKUP(P12,'[4]SERVO CABLE'!G:AD,4,FALSE)),"") -> JZSP-C7M34F-□-E | W12: =IFERROR(VLOOKUP(P12,'[4]SERVO CABLE'!G:AD,17,FALSE),"") -> JZSP-C7PA2D-□-E | Z12: =IF($Y12=1,$R$9,"") | AA12: =IF($Y12=2,$R$9,"") | AB12: =IF($Y12=3,$R$9,"") | AC12: =IF(MID($N11,5,1)<>"W",((700*700)/$Q12*1.509)/1000,"X") -> 0.49294 | AD12: =IF($AC12="X","X",IF($AC12<0.1,"X",IF($AC12<0.27,"IRV60",IF($AC12<0.91,"IRV80",IF($AC12<1.1,"IRV100",IF($AC12<1.3,"IRV120",IF($AC12<1.6,"IRV150",IF($AC12<2.2,"IRV200",IF($AC12<2.7,"IRV300",IF($AC12<4.3,"IRV400",IF($AC12<6.8,"IRV500","X"))))))))))) -> IRV80
A13: TR | D13: DR210A | G13: SCT Main Glass Transfer1 Z-2 | H13: =E13&F13&" "&G13 -> SCT Main Glass Transfer1 Z-2 | I13: =IF(OR(LEFT(O13,3)="SGL",LEFT(O13,5)="SGMCS"),"LINEAR","Rotary") -> Rotary | J13: =IF(OR(RIGHT($H13,1)="Z",LEFT(RIGHT($H13,2),1)="Z",LEFT(RIGHT($H13,3),1)="Z"),"Z",IF(OR(RIGHT($H13,1)="X",LEFT(RIGHT($H13,2),1)="X",LEFT(RIGHT($H13,3),1)="X"),"X",IF(OR(RIGHT($H13,1)="Y",LEFT(RIGHT($H13,2),1)="Y",LEFT(RIGHT($H13,3),1)="Y"),"Y","T"))) -> Z | K13: =VLOOKUP($D13,[4]회선정보!B:F,3,FALSE) -> 0 | L13: =VLOOKUP($D13,[4]회선정보!B:F,4,FALSE) -> A | M13: =VLOOKUP($D13,[4]회선정보!B:F,5,FALSE) -> MP1-1 | O13: SGM7J-08A7A2C | P13: =IFERROR(IF($I13="Rotary",LEFT($O13,9),$O13),"") -> SGM7J-08A | Q13: =IF(MID($N12,5,1)<>"W",VLOOKUP(N13,[4]정격용량!$B$3:$K$633,4,FALSE),"X") -> X | R13: =IF(MID(N12,5,1)<>"W",VLOOKUP(N13,[4]정격용량!$B$3:$K$633,3,FALSE),"X") -> X | S13: =IF(MID(N12,5,1)<>"W",VLOOKUP(N13,[4]정격용량!$B$3:$K$633,6,FALSE),"X") -> X | T13: =IF(MID($N12,5,1)<>"W",S13*$C$85,"X") -> X | U13: =IF(MID($N12,5,1)<>"W",VLOOKUP(N13,[4]정격용량!$B$3:$K$633,9,FALSE),"X") -> X | V13: =IFERROR(IF(J13="Z",VLOOKUP(P13,'[4]SERVO CABLE'!G:AD,8,FALSE),VLOOKUP(P13,'[4]SERVO CABLE'!G:AD,4,FALSE)),"") -> JZSP-C7M34F-□-E | W13: =IFERROR(VLOOKUP(P13,'[4]SERVO CABLE'!G:AD,17,FALSE),"") -> JZSP-C7PA2D-□-E | Y13: 3 | Z13: =IF($Y13=1,$R$9,"") | AA13: =IF($Y13=2,$R$9,"") | AB13: =IF($Y13=3,$R$9,"") -> 0.25 | AC13: =IF(MID($N12,5,1)<>"W",((700*700)/$Q13*1.509)/1000,"X") -> X | AD13: =IF($AC13="X","X",IF($AC13<0.1,"X",IF($AC13<0.27,"IRV60",IF($AC13<0.91,"IRV80",IF($AC13<1.1,"IRV100",IF($AC13<1.3,"IRV120",IF($AC13<1.6,"IRV150",IF($AC13<2.2,"IRV200",IF($AC13<2.7,"IRV300",IF($AC13<4.3,"IRV400",IF($AC13<6.8,"IRV500","X"))))))))))) -> X
A14: TR | D14: DR210B | G14: SCT Main Glass Transfer1 T | H14: =E14&F14&" "&G14 -> SCT Main Glass Transfer1 T | I14: =IF(OR(LEFT(O14,3)="SGL",LEFT(O14,5)="SGMCS"),"LINEAR","Rotary") -> Rotary | J14: =IF(OR(RIGHT($H14,1)="Z",LEFT(RIGHT($H14,2),1)="Z",LEFT(RIGHT($H14,3),1)="Z"),"Z",IF(OR(RIGHT($H14,1)="X",LEFT(RIGHT($H14,2),1)="X",LEFT(RIGHT($H14,3),1)="X"),"X",IF(OR(RIGHT($H14,1)="Y",LEFT(RIGHT($H14,2),1)="Y",LEFT(RIGHT($H14,3),1)="Y"),"Y","T"))) -> T | K14: =VLOOKUP($D14,[4]회선정보!B:F,3,FALSE) -> 0 | L14: =VLOOKUP($D14,[4]회선정보!B:F,4,FALSE) -> B | M14: =VLOOKUP($D14,[4]회선정보!B:F,5,FALSE) -> MP1-1 | N14: VPH 3.3KW(Mechatrolink3) NCR-HE2332A-A-000 | O14: ND400-95LSP (ABS) NMR-SUFJA2A-322AP | P14: =IFERROR(IF($I14="Rotary",LEFT($O14,9),$O14),"") -> ND400-95L | Q14: =IF(MID($N13,5,1)<>"W",VLOOKUP(N14,[4]정격용량!$B$3:$K$633,4,FALSE),"X") -> 3300 | R14: =IF(MID(N13,5,1)<>"W",VLOOKUP(N14,[4]정격용량!$B$3:$K$633,3,FALSE),"X") -> 0.18 | S14: =IF(MID(N13,5,1)<>"W",VLOOKUP(N14,[4]정격용량!$B$3:$K$633,6,FALSE),"X") -> 17 | T14: =IF(MID($N13,5,1)<>"W",S14*$C$85,"X") -> 6.4304348 | U14: =IF(MID($N13,5,1)<>"W",VLOOKUP(N14,[4]정격용량!$B$3:$K$633,9,FALSE),"X") -> 0 | V14: =IFERROR(IF(J14="Z",VLOOKUP(P14,'[4]SERVO CABLE'!G:AD,8,FALSE),VLOOKUP(P14,'[4]SERVO CABLE'!G:AD,4,FALSE)),"") -> NCR-XBBEA-150 | W14: =IFERROR(VLOOKUP(P14,'[4]SERVO CABLE'!G:AD,17,FALSE),"") -> NCR-XBGGA-150 | Z14: =IF($Y14=1,$R$9,"") | AA14: =IF($Y14=2,$R$9,"") | AB14: =IF($Y14=3,$R$9,"") | AC14: =IF(MID($N13,5,1)<>"W",((700*700)/$Q14*1.509)/1000,"X") -> 0.22406364 | AD14: =IF($AC14="X","X",IF($AC14<0.1,"X",IF($AC14<0.27,"IRV60",IF($AC14<0.91,"IRV80",IF($AC14<1.1,"IRV100",IF($AC14<1.3,"IRV120",IF($AC14<1.6,"IRV150",IF($AC14<2.2,"IRV200",IF($AC14<2.7,"IRV300",IF($AC14<4.3,"IRV400",IF($AC14<6.8,"IRV500","X"))))))))))) -> IRV60
A15: TR | D15: DR210D | G15: SCT Main Glass PreAlign Left X | H15: =E15&F15&" "&G15 -> SCT Main Glass PreAlign Left X | I15: =IF(OR(LEFT(O15,3)="SGL",LEFT(O15,5)="SGMCS"),"LINEAR","Rotary") -> Rotary | J15: =IF(OR(RIGHT($H15,1)="Z",LEFT(RIGHT($H15,2),1)="Z",LEFT(RIGHT($H15,3),1)="Z"),"Z",IF(OR(RIGHT($H15,1)="X",LEFT(RIGHT($H15,2),1)="X",LEFT(RIGHT($H15,3),1)="X"),"X",IF(OR(RIGHT($H15,1)="Y",LEFT(RIGHT($H15,2),1)="Y",LEFT(RIGHT($H15,3),1)="Y"),"Y","T"))) -> X | K15: =VLOOKUP($D15,[4]회선정보!B:F,3,FALSE) -> 0 | L15: =VLOOKUP($D15,[4]회선정보!B:F,4,FALSE) -> D | M15: =VLOOKUP($D15,[4]회선정보!B:F,5,FALSE) -> MP1-1 | N15: SGD7W-1R6A20A | O15: SGM7J-01A7A21 | P15: =IFERROR(IF($I15="Rotary",LEFT($O15,9),$O15),"") -> SGM7J-01A | Q15: =IF(MID($N14,5,1)<>"W",VLOOKUP(N15,[4]정격용량!$B$3:$K$633,4,FALSE),"X") -> 400 | R15: =IF(MID(N14,5,1)<>"W",VLOOKUP(N15,[4]정격용량!$B$3:$K$633,3,FALSE),"X") -> 0.3 | S15: =IF(MID(N14,5,1)<>"W",VLOOKUP(N15,[4]정격용량!$B$3:$K$633,6,FALSE),"X") -> 2.5 | T15: =IF(MID($N14,5,1)<>"W",S15*$C$85,"X") -> 0.94565217 | U15: =IF(MID($N14,5,1)<>"W",VLOOKUP(N15,[4]정격용량!$B$3:$K$633,9,FALSE),"X") -> 3 | V15: =IFERROR(IF(J15="Z",VLOOKUP(P15,'[4]SERVO CABLE'!G:AD,8,FALSE),VLOOKUP(P15,'[4]SERVO CABLE'!G:AD,4,FALSE)),"") -> JZSP-C7M12F-□-E | W15: =IFERROR(VLOOKUP(P15,'[4]SERVO CABLE'!G:AD,17,FALSE),"") -> JZSP-C7PA2D-□-E | Y15: 1 | Z15: =IF($Y15=1,$R$9,"") -> 0.25 | AA15: =IF($Y15=2,$R$9,"") | AB15: =IF($Y15=3,$R$9,"") | AC15: =IF(MID($N14,5,1)<>"W",((700*700)/$Q15*1.509)/1000,"X") -> 1.848525 | AD15: =IF($AC15="X","X",IF($AC15<0.1,"X",IF($AC15<0.27,"IRV60",IF($AC15<0.91,"IRV80",IF($AC15<1.1,"IRV100",IF($AC15<1.3,"IRV120",IF($AC15<1.6,"IRV150",IF($AC15<2.2,"IRV200",IF($AC15<2.7,"IRV300",IF($AC15<4.3,"IRV400",IF($AC15<6.8,"IRV500","X"))))))))))) -> IRV200
A16: SC | D16: DR210E | G16: SCT Main Glass PreAlign Right X | H16: =E16&F16&" "&G16 -> SCT Main Glass PreAlign Right X | I16: =IF(OR(LEFT(O16,3)="SGL",LEFT(O16,5)="SGMCS"),"LINEAR","Rotary") -> Rotary | J16: =IF(OR(RIGHT($H16,1)="Z",LEFT(RIGHT($H16,2),1)="Z",LEFT(RIGHT($H16,3),1)="Z"),"Z",IF(OR(RIGHT($H16,1)="X",LEFT(RIGHT($H16,2),1)="X",LEFT(RIGHT($H16,3),1)="X"),"X",IF(OR(RIGHT($H16,1)="Y",LEFT(RIGHT($H16,2),1)="Y",LEFT(RIGHT($H16,3),1)="Y"),"Y","T"))) -> X | K16: =VLOOKUP($D16,[4]회선정보!B:F,3,FALSE) -> 0 | L16: =VLOOKUP($D16,[4]회선정보!B:F,4,FALSE) -> E | M16: =VLOOKUP($D16,[4]회선정보!B:F,5,FALSE) -> MP1-1 | O16: SGM7J-01A7A21 | P16: =IFERROR(IF($I16="Rotary",LEFT($O16,9),$O16),"") -> SGM7J-01A | Q16: =IF(MID($N15,5,1)<>"W",VLOOKUP(N16,[4]정격용량!$B$3:$K$633,4,FALSE),"X") -> X | R16: =IF(MID(N15,5,1)<>"W",VLOOKUP(N16,[4]정격용량!$B$3:$K$633,3,FALSE),"X") -> X | S16: =IF(MID(N15,5,1)<>"W",VLOOKUP(N16,[4]정격용량!$B$3:$K$633,6,FALSE),"X") -> X | T16: =IF(MID($N15,5,1)<>"W",S16*$C$85,"X") -> X | U16: =IF(MID($N15,5,1)<>"W",VLOOKUP(N16,[4]정격용량!$B$3:$K$633,9,FALSE),"X") -> X | V16: =IFERROR(IF(J16="Z",VLOOKUP(P16,'[4]SERVO CABLE'!G:AD,8,FALSE),VLOOKUP(P16,'[4]SERVO CABLE'!G:AD,4,FALSE)),"") -> JZSP-C7M12F-□-E | W16: =IFERROR(VLOOKUP(P16,'[4]SERVO CABLE'!G:AD,17,FALSE),"") -> JZSP-C7PA2D-□-E | Y16: 2 | Z16: =IF($Y16=1,$R$9,"") | AA16: =IF($Y16=2,$R$9,"") -> 0.25 | AB16: =IF($Y16=3,$R$9,"") | AC16: =IF(MID($N15,5,1)<>"W",((700*700)/$Q16*1.509)/1000,"X") -> X | AD16: =IF($AC16="X","X",IF($AC16<0.1,"X",IF($AC16<0.27,"IRV60",IF($AC16<0.91,"IRV80",IF($AC16<1.1,"IRV100",IF($AC16<1.3,"IRV120",IF($AC16<1.6,"IRV150",IF($AC16<2.2,"IRV200",IF($AC16<2.7,"IRV300",IF($AC16<4.3,"IRV400",IF($AC16<6.8,"IRV500","X"))))))))))) -> X
A17: SC | D17: DR210F | G17: SCT Main Glass MCR X | H17: =E17&F17&" "&G17 -> SCT Main Glass MCR X | I17: =IF(OR(LEFT(O17,3)="SGL",LEFT(O17,5)="SGMCS"),"LINEAR","Rotary") -> Rotary | J17: =IF(OR(RIGHT($H17,1)="Z",LEFT(RIGHT($H17,2),1)="Z",LEFT(RIGHT($H17,3),1)="Z"),"Z",IF(OR(RIGHT($H17,1)="X",LEFT(RIGHT($H17,2),1)="X",LEFT(RIGHT($H17,3),1)="X"),"X",IF(OR(RIGHT($H17,1)="Y",LEFT(RIGHT($H17,2),1)="Y",LEFT(RIGHT($H17,3),1)="Y"),"Y","T"))) -> X | K17: =VLOOKUP($D17,[4]회선정보!B:F,3,FALSE) -> 0 | L17: =VLOOKUP($D17,[4]회선정보!B:F,4,FALSE) -> F | M17: =VLOOKUP($D17,[4]회선정보!B:F,5,FALSE) -> MP1-1 | N17: SGD7S-5R5A20A | O17: SGM7J-08A7A21 | P17: =IFERROR(IF($I17="Rotary",LEFT($O17,9),$O17),"") -> SGM7J-08A | Q17: =IF(MID($N16,5,1)<>"W",VLOOKUP(N17,[4]정격용량!$B$3:$K$633,4,FALSE),"X") -> 750 | R17: =IF(MID(N16,5,1)<>"W",VLOOKUP(N17,[4]정격용량!$B$3:$K$633,3,FALSE),"X") -> 0.2 | S17: =IF(MID(N16,5,1)<>"W",VLOOKUP(N17,[4]정격용량!$B$3:$K$633,6,FALSE),"X") -> 4.1 | T17: =IF(MID($N16,5,1)<>"W",S17*$C$85,"X") -> 1.5508696 | U17: =IF(MID($N16,5,1)<>"W",VLOOKUP(N17,[4]정격용량!$B$3:$K$633,9,FALSE),"X") -> 5 | V17: =IFERROR(IF(J17="Z",VLOOKUP(P17,'[4]SERVO CABLE'!G:AD,8,FALSE),VLOOKUP(P17,'[4]SERVO CABLE'!G:AD,4,FALSE)),"") -> JZSP-C7M32F-□-E | W17: =IFERROR(VLOOKUP(P17,'[4]SERVO CABLE'!G:AD,17,FALSE),"") -> JZSP-C7PA2D-□-E | Y17: 3 | Z17: =IF($Y17=1,$R$9,"") | AA17: =IF($Y17=2,$R$9,"") | AB17: =IF($Y17=3,$R$9,"") -> 0.25 | AC17: =IF(MID($N16,5,1)<>"W",((700*700)/$Q17*1.509)/1000,"X") -> 0.98588 | AD17: =IF($AC17="X","X",IF($AC17<0.1,"X",IF($AC17<0.27,"IRV60",IF($AC17<0.91,"IRV80",IF($AC17<1.1,"IRV100",IF($AC17<1.3,"IRV120",IF($AC17<1.6,"IRV150",IF($AC17<2.2,"IRV200",IF($AC17<2.7,"IRV300",IF($AC17<4.3,"IRV400",IF($AC17<6.8,"IRV500","X"))))))))))) -> IRV100
A18: TR | D18: DR2113 | G18: SCT Stick Transfer1 Y-1 | H18: =E18&F18&" "&G18 -> SCT Stick Transfer1 Y-1 | I18: =IF(OR(LEFT(O18,3)="SGL",LEFT(O18,5)="SGMCS"),"LINEAR","Rotary") -> Rotary | J18: =IF(OR(RIGHT($H18,1)="Z",LEFT(RIGHT($H18,2),1)="Z",LEFT(RIGHT($H18,3),1)="Z"),"Z",IF(OR(RIGHT($H18,1)="X",LEFT(RIGHT($H18,2),1)="X",LEFT(RIGHT($H18,3),1)="X"),"X",IF(OR(RIGHT($H18,1)="Y",LEFT(RIGHT($H18,2),1)="Y",LEFT(RIGHT($H18,3),1)="Y"),"Y","T"))) -> Y | K18: =VLOOKUP($D18,[4]회선정보!B:F,3,FALSE) -> 1 | L18: =VLOOKUP($D18,[4]회선정보!B:F,4,FALSE) -> 3 | M18: =VLOOKUP($D18,[4]회선정보!B:F,5,FALSE) -> MP1-2 | N18: SGD7W-7R6A20A | O18: SGM7G-09A7D61 | P18: =IFERROR(IF($I18="Rotary",LEFT($O18,9),$O18),"") -> SGM7G-09A | Q18: =IF(MID($N17,5,1)<>"W",VLOOKUP(N18,[4]정격용량!$B$3:$K$633,4,FALSE),"X") -> 2000 | R18: =IF(MID(N17,5,1)<>"W",VLOOKUP(N18,[4]정격용량!$B$3:$K$633,3,FALSE),"X") -> 0.3 | S18: =IF(MID(N17,5,1)<>"W",VLOOKUP(N18,[4]정격용량!$B$3:$K$633,6,FALSE),"X") -> 11 | T18: =IF(MID($N17,5,1)<>"W",S18*$C$85,"X") -> 4.1608696 | U18: =IF(MID($N17,5,1)<>"W",VLOOKUP(N18,[4]정격용량!$B$3:$K$633,9,FALSE),"X") -> 15 | V18: =IFERROR(IF(J18="Z",VLOOKUP(P18,'[4]SERVO CABLE'!G:AD,8,FALSE),VLOOKUP(P18,'[4]SERVO CABLE'!G:AD,4,FALSE)),"") -> JZSP-UVA122-□-E | W18: =IFERROR(VLOOKUP(P18,'[4]SERVO CABLE'!G:AD,17,FALSE),"") -> JZSP-CVP27-□-E | Y18: 1 | Z18: =IF($Y18=1,$R$9,"") -> 0.25 | AA18: =IF($Y18=2,$R$9,"") | AB18: =IF($Y18=3,$R$9,"") | AC18: =IF(MID($N17,5,1)<>"W",((700*700)/$Q18*1.509)/1000,"X") -> 0.369705 | AD18: =IF($AC18="X","X",IF($AC18<0.1,"X",IF($AC18<0.27,"IRV60",IF($AC18<0.91,"IRV80",IF($AC18<1.1,"IRV100",IF($AC18<1.3,"IRV120",IF($AC18<1.6,"IRV150",IF($AC18<2.2,"IRV200",IF($AC18<2.7,"IRV300",IF($AC18<4.3,"IRV400",IF($AC18<6.8,"IRV500","X"))))))))))) -> IRV80
A19: TR | D19: DR2114 | G19: SCT Stick Transfer1 Y-2 | H19: =E19&F19&" "&G19 -> SCT Stick Transfer1 Y-2 | I19: =IF(OR(LEFT(O19,3)="SGL",LEFT(O19,5)="SGMCS"),"LINEAR","Rotary") -> Rotary | J19: =IF(OR(RIGHT($H19,1)="Z",LEFT(RIGHT($H19,2),1)="Z",LEFT(RIGHT($H19,3),1)="Z"),"Z",IF(OR(RIGHT($H19,1)="X",LEFT(RIGHT($H19,2),1)="X",LEFT(RIGHT($H19,3),1)="X"),"X",IF(OR(RIGHT($H19,1)="Y",LEFT(RIGHT($H19,2),1)="Y",LEFT(RIGHT($H19,3),1)="Y"),"Y","T"))) -> Y | K19: =VLOOKUP($D19,[4]회선정보!B:F,3,FALSE) -> 1 | L19: =VLOOKUP($D19,[4]회선정보!B:F,4,FALSE) -> 4 | M19: =VLOOKUP($D19,[4]회선정보!B:F,5,FALSE) -> MP1-2 | O19: SGM7G-09A7D61 | P19: =IFERROR(IF($I19="Rotary",LEFT($O19,9),$O19),"") -> SGM7G-09A | Q19: =IF(MID($N18,5,1)<>"W",VLOOKUP(N19,[4]정격용량!$B$3:$K$633,4,FALSE),"X") -> X | R19: =IF(MID(N18,5,1)<>"W",VLOOKUP(N19,[4]정격용량!$B$3:$K$633,3,FALSE),"X") -> X | S19: =IF(MID(N18,5,1)<>"W",VLOOKUP(N19,[4]정격용량!$B$3:$K$633,6,FALSE),"X") -> X | T19: =IF(MID($N18,5,1)<>"W",S19*$C$85,"X") -> X | U19: =IF(MID($N18,5,1)<>"W",VLOOKUP(N19,[4]정격용량!$B$3:$K$633,9,FALSE),"X") -> X | V19: =IFERROR(IF(J19="Z",VLOOKUP(P19,'[4]SERVO CABLE'!G:AD,8,FALSE),VLOOKUP(P19,'[4]SERVO CABLE'!G:AD,4,FALSE)),"") -> JZSP-UVA122-□-E | W19: =IFERROR(VLOOKUP(P19,'[4]SERVO CABLE'!G:AD,17,FALSE),"") -> JZSP-CVP27-□-E | Z19: =IF($Y19=1,$R$9,"") | AA19: =IF($Y19=2,$R$9,"") | AB19: =IF($Y19=3,$R$9,"") | AC19: =IF(MID($N18,5,1)<>"W",((700*700)/$Q19*1.509)/1000,"X") -> X | AD19: =IF($AC19="X","X",IF($AC19<0.1,"X",IF($AC19<0.27,"IRV60",IF($AC19<0.91,"IRV80",IF($AC19<1.1,"IRV100",IF($AC19<1.3,"IRV120",IF($AC19<1.6,"IRV150",IF($AC19<2.2,"IRV200",IF($AC19<2.7,"IRV300",IF($AC19<4.3,"IRV400",IF($AC19<6.8,"IRV500","X"))))))))))) -> X
A20: TR | D20: DR2115 | G20: SCT Stick Transfer1 Z-1 | H20: =E20&F20&" "&G20 -> SCT Stick Transfer1 Z-1 | I20: =IF(OR(LEFT(O20,3)="SGL",LEFT(O20,5)="SGMCS"),"LINEAR","Rotary") -> Rotary | J20: =IF(OR(RIGHT($H20,1)="Z",LEFT(RIGHT($H20,2),1)="Z",LEFT(RIGHT($H20,3),1)="Z"),"Z",IF(OR(RIGHT($H20,1)="X",LEFT(RIGHT($H20,2),1)="X",LEFT(RIGHT($H20,3),1)="X"),"X",IF(OR(RIGHT($H20,1)="Y",LEFT(RIGHT($H20,2),1)="Y",LEFT(RIGHT($H20,3),1)="Y"),"Y","T"))) -> Z | K20: =VLOOKUP($D20,[4]회선정보!B:F,3,FALSE) -> 1 | L20: =VLOOKUP($D20,[4]회선정보!B:F,4,FALSE) -> 5 | M20: =VLOOKUP($D20,[4]회선정보!B:F,5,FALSE) -> MP1-2 | N20: SGD7W-5R5A20A | O20: SGM7J-08A7A2C | P20: =IFERROR(IF($I20="Rotary",LEFT($O20,9),$O20),"") -> SGM7J-08A | Q20: =IF(MID($N19,5,1)<>"W",VLOOKUP(N20,[4]정격용량!$B$3:$K$633,4,FALSE),"X") -> 1500 | R20: =IF(MID(N19,5,1)<>"W",VLOOKUP(N20,[4]정격용량!$B$3:$K$633,3,FALSE),"X") -> 0.3 | S20: =IF(MID(N19,5,1)<>"W",VLOOKUP(N20,[4]정격용량!$B$3:$K$633,6,FALSE),"X") -> 7.8 | T20: =IF(MID($N19,5,1)<>"W",S20*$C$85,"X") -> 2.9504348 | U20: =IF(MID($N19,5,1)<>"W",VLOOKUP(N20,[4]정격용량!$B$3:$K$633,9,FALSE),"X") -> 10 | V20: =IFERROR(IF(J20="Z",VLOOKUP(P20,'[4]SERVO CABLE'!G:AD,8,FALSE),VLOOKUP(P20,'[4]SERVO CABLE'!G:AD,4,FALSE)),"") -> JZSP-C7M34F-□-E | W20: =IFERROR(VLOOKUP(P20,'[4]SERVO CABLE'!G:AD,17,FALSE),"") -> JZSP-C7PA2D-□-E | Y20: 2 | Z20: =IF($Y20=1,$R$9,"") | AA20: =IF($Y20=2,$R$9,"") -> 0.25 | AB20: =IF($Y20=3,$R$9,"") | AC20: =IF(MID($N19,5,1)<>"W",((700*700)/$Q20*1.509)/1000,"X") -> 0.49294 | AD20: =IF($AC20="X","X",IF($AC20<0.1,"X",IF($AC20<0.27,"IRV60",IF($AC20<0.91,"IRV80",IF($AC20<1.1,"IRV100",IF($AC20<1.3,"IRV120",IF($AC20<1.6,"IRV150",IF($AC20<2.2,"IRV200",IF($AC20<2.7,"IRV300",IF($AC20<4.3,"IRV400",IF($AC20<6.8,"IRV500","X"))))))))))) -> IRV80
A21: TR | D21: DR2116 | G21: SCT Stick Transfer1 Z-2 | H21: =E21&F21&" "&G21 -> SCT Stick Transfer1 Z-2 | I21: =IF(OR(LEFT(O21,3)="SGL",LEFT(O21,5)="SGMCS"),"LINEAR","Rotary") -> Rotary | J21: =IF(OR(RIGHT($H21,1)="Z",LEFT(RIGHT($H21,2),1)="Z",LEFT(RIGHT($H21,3),1)="Z"),"Z",IF(OR(RIGHT($H21,1)="X",LEFT(RIGHT($H21,2),1)="X",LEFT(RIGHT($H21,3),1)="X"),"X",IF(OR(RIGHT($H21,1)="Y",LEFT(RIGHT($H21,2),1)="Y",LEFT(RIGHT($H21,3),1)="Y"),"Y","T"))) -> Z | K21: =VLOOKUP($D21,[4]회선정보!B:F,3,FALSE) -> 1 | L21: =VLOOKUP($D21,[4]회선정보!B:F,4,FALSE) -> 6 | M21: =VLOOKUP($D21,[4]회선정보!B:F,5,FALSE) -> MP1-2 | O21: SGM7J-08A7A2C | P21: =IFERROR(IF($I21="Rotary",LEFT($O21,9),$O21),"") -> SGM7J-08A | Q21: =IF(MID($N20,5,1)<>"W",VLOOKUP(N21,[4]정격용량!$B$3:$K$633,4,FALSE),"X") -> X | R21: =IF(MID(N20,5,1)<>"W",VLOOKUP(N21,[4]정격용량!$B$3:$K$633,3,FALSE),"X") -> X | S21: =IF(MID(N20,5,1)<>"W",VLOOKUP(N21,[4]정격용량!$B$3:$K$633,6,FALSE),"X") -> X | T21: =IF(MID($N20,5,1)<>"W",S21*$C$85,"X") -> X | U21: =IF(MID($N20,5,1)<>"W",VLOOKUP(N21,[4]정격용량!$B$3:$K$633,9,FALSE),"X") -> X | V21: =IFERROR(IF(J21="Z",VLOOKUP(P21,'[4]SERVO CABLE'!G:AD,8,FALSE),VLOOKUP(P21,'[4]SERVO CABLE'!G:AD,4,FALSE)),"") -> JZSP-C7M34F-□-E | W21: =IFERROR(VLOOKUP(P21,'[4]SERVO CABLE'!G:AD,17,FALSE),"") -> JZSP-C7PA2D-□-E | Y21: 3 | Z21: =IF($Y21=1,$R$9,"") | AA21: =IF($Y21=2,$R$9,"") | AB21: =IF($Y21=3,$R$9,"") -> 0.25 | AC21: =IF(MID($N20,5,1)<>"W",((700*700)/$Q21*1.509)/1000,"X") -> X | AD21: =IF($AC21="X","X",IF($AC21<0.1,"X",IF($AC21<0.27,"IRV60",IF($AC21<0.91,"IRV80",IF($AC21<1.1,"IRV100",IF($AC21<1.3,"IRV120",IF($AC21<1.6,"IRV150",IF($AC21<2.2,"IRV200",IF($AC21<2.7,"IRV300",IF($AC21<4.3,"IRV400",IF($AC21<6.8,"IRV500","X"))))))))))) -> X
A22: TR | D22: DR2118 | G22: SCT Stick Buffer Table Y | H22: =E22&F22&" "&G22 -> SCT Stick Buffer Table Y | I22: =IF(OR(LEFT(O22,3)="SGL",LEFT(O22,5)="SGMCS"),"LINEAR","Rotary") -> Rotary | J22: =IF(OR(RIGHT($H22,1)="Z",LEFT(RIGHT($H22,2),1)="Z",LEFT(RIGHT($H22,3),1)="Z"),"Z",IF(OR(RIGHT($H22,1)="X",LEFT(RIGHT($H22,2),1)="X",LEFT(RIGHT($H22,3),1)="X"),"X",IF(OR(RIGHT($H22,1)="Y",LEFT(RIGHT($H22,2),1)="Y",LEFT(RIGHT($H22,3),1)="Y"),"Y","T"))) -> Y | K22: =VLOOKUP($D22,[4]회선정보!B:F,3,FALSE) -> 1 | L22: =VLOOKUP($D22,[4]회선정보!B:F,4,FALSE) -> 8 | M22: =VLOOKUP($D22,[4]회선정보!B:F,5,FALSE) -> MP1-2 | N22: SGD7S-7R6A20A | O22: SGM7G-09A7D61 | P22: =IFERROR(IF($I22="Rotary",LEFT($O22,9),$O22),"") -> SGM7G-09A | Q22: =IF(MID($N21,5,1)<>"W",VLOOKUP(N22,[4]정격용량!$B$3:$K$633,4,FALSE),"X") -> 1000 | R22: =IF(MID(N21,5,1)<>"W",VLOOKUP(N22,[4]정격용량!$B$3:$K$633,3,FALSE),"X") -> 0.2 | S22: =IF(MID(N21,5,1)<>"W",VLOOKUP(N22,[4]정격용량!$B$3:$K$633,6,FALSE),"X") -> 5.7 | T22: =IF(MID($N21,5,1)<>"W",S22*$C$85,"X") -> 2.156087 | U22: =IF(MID($N21,5,1)<>"W",VLOOKUP(N22,[4]정격용량!$B$3:$K$633,9,FALSE),"X") -> 7 | V22: =IFERROR(IF(J22="Z",VLOOKUP(P22,'[4]SERVO CABLE'!G:AD,8,FALSE),VLOOKUP(P22,'[4]SERVO CABLE'!G:AD,4,FALSE)),"") -> JZSP-UVA122-□-E | W22: =IFERROR(VLOOKUP(P22,'[4]SERVO CABLE'!G:AD,17,FALSE),"") -> JZSP-CVP27-□-E | Z22: =IF($Y22=1,$R$9,"") | AA22: =IF($Y22=2,$R$9,"") | AB22: =IF($Y22=3,$R$9,"") | AC22: =IF(MID($N21,5,1)<>"W",((700*700)/$Q22*1.509)/1000,"X") -> 0.73941 | AD22: =IF($AC22="X","X",IF($AC22<0.1,"X",IF($AC22<0.27,"IRV60",IF($AC22<0.91,"IRV80",IF($AC22<1.1,"IRV100",IF($AC22<1.3,"IRV120",IF($AC22<1.6,"IRV150",IF($AC22<2.2,"IRV200",IF($AC22<2.7,"IRV300",IF($AC22<4.3,"IRV400",IF($AC22<6.8,"IRV500","X"))))))))))) -> IRV80
A23: TR | D23: DR2119 | G23: SCT Stick Buffer Table T | H23: =E23&F23&" "&G23 -> SCT Stick Buffer Table T | I23: =IF(OR(LEFT(O23,3)="SGL",LEFT(O23,5)="SGMCS"),"LINEAR","Rotary") -> Rotary | J23: =IF(OR(RIGHT($H23,1)="Z",LEFT(RIGHT($H23,2),1)="Z",LEFT(RIGHT($H23,3),1)="Z"),"Z",IF(OR(RIGHT($H23,1)="X",LEFT(RIGHT($H23,2),1)="X",LEFT(RIGHT($H23,3),1)="X"),"X",IF(OR(RIGHT($H23,1)="Y",LEFT(RIGHT($H23,2),1)="Y",LEFT(RIGHT($H23,3),1)="Y"),"Y","T"))) -> T | K23: =VLOOKUP($D23,[4]회선정보!B:F,3,FALSE) -> 1 | L23: =VLOOKUP($D23,[4]회선정보!B:F,4,FALSE) -> 9 | M23: =VLOOKUP($D23,[4]회선정보!B:F,5,FALSE) -> MP1-2 | N23: VPH 2.2KW (Mechatrolink3) NCR-HE2222A-A-000 | O23: ND400-70LSP (ABS) NMR-SUEJA2A-182AP | P23: =IFERROR(IF($I23="Rotary",LEFT($O23,9),$O23),"") -> ND400-70L | Q23: =IF(MID($N22,5,1)<>"W",VLOOKUP(N23,[4]정격용량!$B$3:$K$633,4,FALSE),"X") -> 2200 | R23: =IF(MID(N22,5,1)<>"W",VLOOKUP(N23,[4]정격용량!$B$3:$K$633,3,FALSE),"X") -> 0.15 | S23: =IF(MID(N22,5,1)<>"W",VLOOKUP(N23,[4]정격용량!$B$3:$K$633,6,FALSE),"X") -> 13.5 | T23: =IF(MID($N22,5,1)<>"W",S23*$C$85,"X") -> 5.1065217 | U23: =IF(MID($N22,5,1)<>"W",VLOOKUP(N23,[4]정격용량!$B$3:$K$633,9,FALSE),"X") -> 0 | V23: =IFERROR(IF(J23="Z",VLOOKUP(P23,'[4]SERVO CABLE'!G:AD,8,FALSE),VLOOKUP(P23,'[4]SERVO CABLE'!G:AD,4,FALSE)),"") -> NCR-XBBEA-150 | W23: =IFERROR(VLOOKUP(P23,'[4]SERVO CABLE'!G:AD,17,FALSE),"") -> NCR-XBGGA-150 | Z23: =IF($Y23=1,$R$9,"") | AA23: =IF($Y23=2,$R$9,"") | AB23: =IF($Y23=3,$R$9,"") | AC23: =IF(MID($N22,5,1)<>"W",((700*700)/$Q23*1.509)/1000,"X") -> 0.33609545 | AD23: =IF($AC23="X","X",IF($AC23<0.1,"X",IF($AC23<0.27,"IRV60",IF($AC23<0.91,"IRV80",IF($AC23<1.1,"IRV100",IF($AC23<1.3,"IRV120",IF($AC23<1.6,"IRV150",IF($AC23<2.2,"IRV200",IF($AC23<2.7,"IRV300",IF($AC23<4.3,"IRV400",IF($AC23<6.8,"IRV500","X"))))))))))) -> IRV80
A24: RE | D24: DR211B | G24: SCT Stick PreAlign Left X | H24: =E24&F24&" "&G24 -> SCT Stick PreAlign Left X | I24: =IF(OR(LEFT(O24,3)="SGL",LEFT(O24,5)="SGMCS"),"LINEAR","Rotary") -> Rotary | J24: =IF(OR(RIGHT($H24,1)="Z",LEFT(RIGHT($H24,2),1)="Z",LEFT(RIGHT($H24,3),1)="Z"),"Z",IF(OR(RIGHT($H24,1)="X",LEFT(RIGHT($H24,2),1)="X",LEFT(RIGHT($H24,3),1)="X"),"X",IF(OR(RIGHT($H24,1)="Y",LEFT(RIGHT($H24,2),1)="Y",LEFT(RIGHT($H24,3),1)="Y"),"Y","T"))) -> X | K24: =VLOOKUP($D24,[4]회선정보!B:F,3,FALSE) -> 1 | L24: =VLOOKUP($D24,[4]회선정보!B:F,4,FALSE) -> B | M24: =VLOOKUP($D24,[4]회선정보!B:F,5,FALSE) -> MP1-2 | N24: SGD7W-1R6A20A | O24: SGM7J-01A7A21 | P24: =IFERROR(IF($I24="Rotary",LEFT($O24,9),$O24),"") -> SGM7J-01A | Q24: =IF(MID($N23,5,1)<>"W",VLOOKUP(N24,[4]정격용량!$B$3:$K$633,4,FALSE),"X") -> 400 | R24: =IF(MID(N23,5,1)<>"W",VLOOKUP(N24,[4]정격용량!$B$3:$K$633,3,FALSE),"X") -> 0.3 | S24: =IF(MID(N23,5,1)<>"W",VLOOKUP(N24,[4]정격용량!$B$3:$K$633,6,FALSE),"X") -> 2.5 | T24: =IF(MID($N23,5,1)<>"W",S24*$C$85,"X") -> 0.94565217 | U24: =IF(MID($N23,5,1)<>"W",VLOOKUP(N24,[4]정격용량!$B$3:$K$633,9,FALSE),"X") -> 3 | V24: =IFERROR(IF(J24="Z",VLOOKUP(P24,'[4]SERVO CABLE'!G:AD,8,FALSE),VLOOKUP(P24,'[4]SERVO CABLE'!G:AD,4,FALSE)),"") -> JZSP-C7M12F-□-E | W24: =IFERROR(VLOOKUP(P24,'[4]SERVO CABLE'!G:AD,17,FALSE),"") -> JZSP-C7PA2D-□-E | Y24: 1 | Z24: =IF($Y24=1,$R$9,"") -> 0.25 | AA24: =IF($Y24=2,$R$9,"") | AB24: =IF($Y24=3,$R$9,"") | AC24: =IF(MID($N23,5,1)<>"W",((700*700)/$Q24*1.509)/1000,"X") -> 1.848525 | AD24: =IF($AC24="X","X",IF($AC24<0.1,"X",IF($AC24<0.27,"IRV60",IF($AC24<0.91,"IRV80",IF($AC24<1.1,"IRV100",IF($AC24<1.3,"IRV120",IF($AC24<1.6,"IRV150",IF($AC24<2.2,"IRV200",IF($AC24<2.7,"IRV300",IF($AC24<4.3,"IRV400",IF($AC24<6.8,"IRV500","X"))))))))))) -> IRV200
A25: RE | D25: DR211C | G25: SCT Stick PreAlign Right X | H25: =E25&F25&" "&G25 -> SCT Stick PreAlign Right X | I25: =IF(OR(LEFT(O25,3)="SGL",LEFT(O25,5)="SGMCS"),"LINEAR","Rotary") -> Rotary | J25: =IF(OR(RIGHT($H25,1)="Z",LEFT(RIGHT($H25,2),1)="Z",LEFT(RIGHT($H25,3),1)="Z"),"Z",IF(OR(RIGHT($H25,1)="X",LEFT(RIGHT($H25,2),1)="X",LEFT(RIGHT($H25,3),1)="X"),"X",IF(OR(RIGHT($H25,1)="Y",LEFT(RIGHT($H25,2),1)="Y",LEFT(RIGHT($H25,3),1)="Y"),"Y","T"))) -> X | K25: =VLOOKUP($D25,[4]회선정보!B:F,3,FALSE) -> 1 | L25: =VLOOKUP($D25,[4]회선정보!B:F,4,FALSE) -> C | M25: =VLOOKUP($D25,[4]회선정보!B:F,5,FALSE) -> MP1-2 | O25: SGM7J-01A7A21 | P25: =IFERROR(IF($I25="Rotary",LEFT($O25,9),$O25),"") -> SGM7J-01A | Q25: =IF(MID($N24,5,1)<>"W",VLOOKUP(N25,[4]정격용량!$B$3:$K$633,4,FALSE),"X") -> X | R25: =IF(MID(N24,5,1)<>"W",VLOOKUP(N25,[4]정격용량!$B$3:$K$633,3,FALSE),"X") -> X | S25: =IF(MID(N24,5,1)<>"W",VLOOKUP(N25,[4]정격용량!$B$3:$K$633,6,FALSE),"X") -> X | T25: =IF(MID($N24,5,1)<>"W",S25*$C$85,"X") -> X | U25: =IF(MID($N24,5,1)<>"W",VLOOKUP(N25,[4]정격용량!$B$3:$K$633,9,FALSE),"X") -> X | V25: =IFERROR(IF(J25="Z",VLOOKUP(P25,'[4]SERVO CABLE'!G:AD,8,FALSE),VLOOKUP(P25,'[4]SERVO CABLE'!G:AD,4,FALSE)),"") -> JZSP-C7M12F-□-E | W25: =IFERROR(VLOOKUP(P25,'[4]SERVO CABLE'!G:AD,17,FALSE),"") -> JZSP-C7PA2D-□-E | Z25: =IF($Y25=1,$R$9,"") | AA25: =IF($Y25=2,$R$9,"") | AB25: =IF($Y25=3,$R$9,"") | AC25: =IF(MID($N24,5,1)<>"W",((700*700)/$Q25*1.509)/1000,"X") -> X | AD25: =IF($AC25="X","X",IF($AC25<0.1,"X",IF($AC25<0.27,"IRV60",IF($AC25<0.91,"IRV80",IF($AC25<1.1,"IRV100",IF($AC25<1.3,"IRV120",IF($AC25<1.6,"IRV150",IF($AC25<2.2,"IRV200",IF($AC25<2.7,"IRV300",IF($AC25<4.3,"IRV400",IF($AC25<6.8,"IRV500","X"))))))))))) -> X
A26: RE | D26: DR2503 | G26: SCT Cutter X | H26: =E26&F26&" "&G26 -> SCT Cutter X | I26: =IF(OR(LEFT(O26,3)="SGL",LEFT(O26,5)="SGMCS"),"LINEAR","Rotary") -> LINEAR | J26: =IF(OR(RIGHT($H26,1)="Z",LEFT(RIGHT($H26,2),1)="Z",LEFT(RIGHT($H26,3),1)="Z"),"Z",IF(OR(RIGHT($H26,1)="X",LEFT(RIGHT($H26,2),1)="X",LEFT(RIGHT($H26,3),1)="X"),"X",IF(OR(RIGHT($H26,1)="Y",LEFT(RIGHT($H26,2),1)="Y",LEFT(RIGHT($H26,3),1)="Y"),"Y","T"))) -> X | K26: =VLOOKUP($D26,[4]회선정보!B:F,3,FALSE) -> 0 | L26: =VLOOKUP($D26,[4]회선정보!B:F,4,FALSE) -> 3 | M26: =VLOOKUP($D26,[4]회선정보!B:F,5,FALSE) -> MP5-1 | N26: SGD7W-1R6A20A | O26: SGLGW-60A140C | P26: =IFERROR(IF($I26="Rotary",LEFT($O26,9),$O26),"") -> SGLGW-60A140C | Q26: =IF(MID($N25,5,1)<>"W",VLOOKUP(N26,[4]정격용량!$B$3:$K$633,4,FALSE),"X") -> 400 | R26: =IF(MID(N25,5,1)<>"W",VLOOKUP(N26,[4]정격용량!$B$3:$K$633,3,FALSE),"X") -> 0.3 | S26: =IF(MID(N25,5,1)<>"W",VLOOKUP(N26,[4]정격용량!$B$3:$K$633,6,FALSE),"X") -> 2.5 | T26: =IF(MID($N25,5,1)<>"W",S26*$C$85,"X") -> 0.94565217 | U26: =IF(MID($N25,5,1)<>"W",VLOOKUP(N26,[4]정격용량!$B$3:$K$633,9,FALSE),"X") -> 3 | V26: =IFERROR(IF(J26="Z",VLOOKUP(P26,'[4]SERVO CABLE'!G:AD,8,FALSE),VLOOKUP(P26,'[4]SERVO CABLE'!G:AD,4,FALSE)),"") -> JZSP-CLN11-□ | W26: =IFERROR(VLOOKUP(P26,'[4]SERVO CABLE'!G:AD,17,FALSE),"") -> JZSP-CLP70-□-ER | Y26: 2 | Z26: =IF($Y26=1,$R$9,"") | AA26: =IF($Y26=2,$R$9,"") -> 0.25 | AB26: =IF($Y26=3,$R$9,"") | AC26: =IF(MID($N25,5,1)<>"W",((700*700)/$Q26*1.509)/1000,"X") -> 1.848525 | AD26: =IF($AC26="X","X",IF($AC26<0.1,"X",IF($AC26<0.27,"IRV60",IF($AC26<0.91,"IRV80",IF($AC26<1.1,"IRV100",IF($AC26<1.3,"IRV120",IF($AC26<1.6,"IRV150",IF($AC26<2.2,"IRV200",IF($AC26<2.7,"IRV300",IF($AC26<4.3,"IRV400",IF($AC26<6.8,"IRV500","X"))))))))))) -> IRV200
A27: SC | D27: DR2504 | G27: SCT Camera X | H27: =E27&F27&" "&G27 -> SCT Camera X | I27: =IF(OR(LEFT(O27,3)="SGL",LEFT(O27,5)="SGMCS"),"LINEAR","Rotary") -> LINEAR | J27: =IF(OR(RIGHT($H27,1)="Z",LEFT(RIGHT($H27,2),1)="Z",LEFT(RIGHT($H27,3),1)="Z"),"Z",IF(OR(RIGHT($H27,1)="X",LEFT(RIGHT($H27,2),1)="X",LEFT(RIGHT($H27,3),1)="X"),"X",IF(OR(RIGHT($H27,1)="Y",LEFT(RIGHT($H27,2),1)="Y",LEFT(RIGHT($H27,3),1)="Y"),"Y","T"))) -> X | K27: =VLOOKUP($D27,[4]회선정보!B:F,3,FALSE) -> 0 | L27: =VLOOKUP($D27,[4]회선정보!B:F,4,FALSE) -> 4 | M27: =VLOOKUP($D27,[4]회선정보!B:F,5,FALSE) -> MP5-1 | O27: SGLGW-60A140C | P27: =IFERROR(IF($I27="Rotary",LEFT($O27,9),$O27),"") -> SGLGW-60A140C | Q27: =IF(MID($N26,5,1)<>"W",VLOOKUP(N27,[4]정격용량!$B$3:$K$633,4,FALSE),"X") -> X | R27: =IF(MID(N26,5,1)<>"W",VLOOKUP(N27,[4]정격용량!$B$3:$K$633,3,FALSE),"X") -> X | S27: =IF(MID(N26,5,1)<>"W",VLOOKUP(N27,[4]정격용량!$B$3:$K$633,6,FALSE),"X") -> X | T27: =IF(MID($N26,5,1)<>"W",S27*$C$85,"X") -> X | U27: =IF(MID($N26,5,1)<>"W",VLOOKUP(N27,[4]정격용량!$B$3:$K$633,9,FALSE),"X") -> X | V27: =IFERROR(IF(J27="Z",VLOOKUP(P27,'[4]SERVO CABLE'!G:AD,8,FALSE),VLOOKUP(P27,'[4]SERVO CABLE'!G:AD,4,FALSE)),"") -> JZSP-CLN11-□ | W27: =IFERROR(VLOOKUP(P27,'[4]SERVO CABLE'!G:AD,17,FALSE),"") -> JZSP-CLP70-□-ER | Y27: 3 | Z27: =IF($Y27=1,$R$9,"") | AA27: =IF($Y27=2,$R$9,"") | AB27: =IF($Y27=3,$R$9,"") -> 0.25 | AC27: =IF(MID($N26,5,1)<>"W",((700*700)/$Q27*1.509)/1000,"X") -> X | AD27: =IF($AC27="X","X",IF($AC27<0.1,"X",IF($AC27<0.27,"IRV60",IF($AC27<0.91,"IRV80",IF($AC27<1.1,"IRV100",IF($AC27<1.3,"IRV120",IF($AC27<1.6,"IRV150",IF($AC27<2.2,"IRV200",IF($AC27<2.7,"IRV300",IF($AC27<4.3,"IRV400",IF($AC27<6.8,"IRV500","X"))))))))))) -> X
A28: SC | D28: DR2505 | G28: SCT Cutter Z | H28: =E28&F28&" "&G28 -> SCT Cutter Z | I28: =IF(OR(LEFT(O28,3)="SGL",LEFT(O28,5)="SGMCS"),"LINEAR","Rotary") -> Rotary | J28: =IF(OR(RIGHT($H28,1)="Z",LEFT(RIGHT($H28,2),1)="Z",LEFT(RIGHT($H28,3),1)="Z"),"Z",IF(OR(RIGHT($H28,1)="X",LEFT(RIGHT($H28,2),1)="X",LEFT(RIGHT($H28,3),1)="X"),"X",IF(OR(RIGHT($H28,1)="Y",LEFT(RIGHT($H28,2),1)="Y",LEFT(RIGHT($H28,3),1)="Y"),"Y","T"))) -> Z | K28: =VLOOKUP($D28,[4]회선정보!B:F,3,FALSE) -> 0 | L28: =VLOOKUP($D28,[4]회선정보!B:F,4,FALSE) -> 5 | M28: =VLOOKUP($D28,[4]회선정보!B:F,5,FALSE) -> MP5-1 | N28: SGD7S-R70A20A | O28: SGM7A-A5A7A21 | P28: =IFERROR(IF($I28="Rotary",LEFT($O28,9),$O28),"") -> SGM7A-A5A | Q28: =IF(MID($N27,5,1)<>"W",VLOOKUP(N28,[4]정격용량!$B$3:$K$633,4,FALSE),"X") -> 50 | R28: =IF(MID(N27,5,1)<>"W",VLOOKUP(N28,[4]정격용량!$B$3:$K$633,3,FALSE),"X") -> 0.2 | S28: =IF(MID(N27,5,1)<>"W",VLOOKUP(N28,[4]정격용량!$B$3:$K$633,6,FALSE),"X") -> 0.4 | T28: =IF(MID($N27,5,1)<>"W",S28*$C$85,"X") -> 0.15130435 | U28: =IF(MID($N27,5,1)<>"W",VLOOKUP(N28,[4]정격용량!$B$3:$K$633,9,FALSE),"X") -> 1 | V28: =IFERROR(IF(J28="Z",VLOOKUP(P28,'[4]SERVO CABLE'!G:AD,8,FALSE),VLOOKUP(P28,'[4]SERVO CABLE'!G:AD,4,FALSE)),"") -> JZSP-C7M14F-□-E | W28: =IFERROR(VLOOKUP(P28,'[4]SERVO CABLE'!G:AD,17,FALSE),"") -> JZSP-C7PA2D-□-E | Z28: =IF($Y28=1,$R$9,"") | AA28: =IF($Y28=2,$R$9,"") | AB28: =IF($Y28=3,$R$9,"") | AC28: =IF(MID($N27,5,1)<>"W",((700*700)/$Q28*1.509)/1000,"X") -> 14.7882 | AD28: =IF($AC28="X","X",IF($AC28<0.1,"X",IF($AC28<0.27,"IRV60",IF($AC28<0.91,"IRV80",IF($AC28<1.1,"IRV100",IF($AC28<1.3,"IRV120",IF($AC28<1.6,"IRV150",IF($AC28<2.2,"IRV200",IF($AC28<2.7,"IRV300",IF($AC28<4.3,"IRV400",IF($AC28<6.8,"IRV500","X"))))))))))) -> X
A29: SC | D29: DR2506 | G29: SCT Cutter Shift | H29: =E29&F29&" "&G29 -> SCT Cutter Shift | I29: =IF(OR(LEFT(O29,3)="SGL",LEFT(O29,5)="SGMCS"),"LINEAR","Rotary") -> Rotary | J29: =IF(OR(RIGHT($H29,1)="Z",LEFT(RIGHT($H29,2),1)="Z",LEFT(RIGHT($H29,3),1)="Z"),"Z",IF(OR(RIGHT($H29,1)="X",LEFT(RIGHT($H29,2),1)="X",LEFT(RIGHT($H29,3),1)="X"),"X",IF(OR(RIGHT($H29,1)="Y",LEFT(RIGHT($H29,2),1)="Y",LEFT(RIGHT($H29,3),1)="Y"),"Y","T"))) -> T | K29: =VLOOKUP($D29,[4]회선정보!B:F,3,FALSE) -> 0 | L29: =VLOOKUP($D29,[4]회선정보!B:F,4,FALSE) -> 6 | M29: =VLOOKUP($D29,[4]회선정보!B:F,5,FALSE) -> MP5-1 | N29: SGD7S-R70A20A | O29: SGM7A-A5A7A21 | P29: =IFERROR(IF($I29="Rotary",LEFT($O29,9),$O29),"") -> SGM7A-A5A | Q29: =IF(MID($N28,5,1)<>"W",VLOOKUP(N29,[4]정격용량!$B$3:$K$633,4,FALSE),"X") -> 50 | R29: =IF(MID(N28,5,1)<>"W",VLOOKUP(N29,[4]정격용량!$B$3:$K$633,3,FALSE),"X") -> 0.2 | S29: =IF(MID(N28,5,1)<>"W",VLOOKUP(N29,[4]정격용량!$B$3:$K$633,6,FALSE),"X") -> 0.4 | T29: =IF(MID($N28,5,1)<>"W",S29*$C$85,"X") -> 0.15130435 | U29: =IF(MID($N28,5,1)<>"W",VLOOKUP(N29,[4]정격용량!$B$3:$K$633,9,FALSE),"X") -> 1 | V29: =IFERROR(IF(J29="Z",VLOOKUP(P29,'[4]SERVO CABLE'!G:AD,8,FALSE),VLOOKUP(P29,'[4]SERVO CABLE'!G:AD,4,FALSE)),"") -> JZSP-C7M12F-□-E | W29: =IFERROR(VLOOKUP(P29,'[4]SERVO CABLE'!G:AD,17,FALSE),"") -> JZSP-C7PA2D-□-E | Y29: 1 | Z29: =IF($Y29=1,$R$9,"") -> 0.25 | AA29: =IF($Y29=2,$R$9,"") | AB29: =IF($Y29=3,$R$9,"") | AC29: =IF(MID($N28,5,1)<>"W",((700*700)/$Q29*1.509)/1000,"X") -> 14.7882 | AD29: =IF($AC29="X","X",IF($AC29<0.1,"X",IF($AC29<0.27,"IRV60",IF($AC29<0.91,"IRV80",IF($AC29<1.1,"IRV100",IF($AC29<1.3,"IRV120",IF($AC29<1.6,"IRV150",IF($AC29<2.2,"IRV200",IF($AC29<2.7,"IRV300",IF($AC29<4.3,"IRV400",IF($AC29<6.8,"IRV500","X"))))))))))) -> X
A30: SC | D30: DR2508 | G30: SCT Left Camera Y | H30: =E30&F30&" "&G30 -> SCT Left Camera Y | I30: =IF(OR(LEFT(O30,3)="SGL",LEFT(O30,5)="SGMCS"),"LINEAR","Rotary") -> Rotary | J30: =IF(OR(RIGHT($H30,1)="Z",LEFT(RIGHT($H30,2),1)="Z",LEFT(RIGHT($H30,3),1)="Z"),"Z",IF(OR(RIGHT($H30,1)="X",LEFT(RIGHT($H30,2),1)="X",LEFT(RIGHT($H30,3),1)="X"),"X",IF(OR(RIGHT($H30,1)="Y",LEFT(RIGHT($H30,2),1)="Y",LEFT(RIGHT($H30,3),1)="Y"),"Y","T"))) -> Y | K30: =VLOOKUP($D30,[4]회선정보!B:F,3,FALSE) -> 0 | L30: =VLOOKUP($D30,[4]회선정보!B:F,4,FALSE) -> 8 | M30: =VLOOKUP($D30,[4]회선정보!B:F,5,FALSE) -> MP5-1 | N30: SGD7W-1R6A20A | O30: SGM7M-A3A3A21 | P30: =IFERROR(IF($I30="Rotary",LEFT($O30,9),$O30),"") -> SGM7M-A3A | Q30: =IF(MID($N29,5,1)<>"W",VLOOKUP(N30,[4]정격용량!$B$3:$K$633,4,FALSE),"X") -> 400 | R30: =IF(MID(N29,5,1)<>"W",VLOOKUP(N30,[4]정격용량!$B$3:$K$633,3,FALSE),"X") -> 0.3 | S30: =IF(MID(N29,5,1)<>"W",VLOOKUP(N30,[4]정격용량!$B$3:$K$633,6,FALSE),"X") -> 2.5 | T30: =IF(MID($N29,5,1)<>"W",S30*$C$85,"X") -> 0.94565217 | U30: =IF(MID($N29,5,1)<>"W",VLOOKUP(N30,[4]정격용량!$B$3:$K$633,9,FALSE),"X") -> 3 | V30: =IFERROR(IF(J30="Z",VLOOKUP(P30,'[4]SERVO CABLE'!G:AD,8,FALSE),VLOOKUP(P30,'[4]SERVO CABLE'!G:AD,4,FALSE)),"") -> JZSP-CF2M20-□-E | W30: =IFERROR(VLOOKUP(P30,'[4]SERVO CABLE'!G:AD,17,FALSE),"") -> JZSP-C7MP29-□-E | Z30: =IF($Y30=1,$R$9,"") | AA30: =IF($Y30=2,$R$9,"") | AB30: =IF($Y30=3,$R$9,"") | AC30: =IF(MID($N29,5,1)<>"W",((700*700)/$Q30*1.509)/1000,"X") -> 1.848525 | AD30: =IF($AC30="X","X",IF($AC30<0.1,"X",IF($AC30<0.27,"IRV60",IF($AC30<0.91,"IRV80",IF($AC30<1.1,"IRV100",IF($AC30<1.3,"IRV120",IF($AC30<1.6,"IRV150",IF($AC30<2.2,"IRV200",IF($AC30<2.7,"IRV300",IF($AC30<4.3,"IRV400",IF($AC30<6.8,"IRV500","X"))))))))))) -> IRV200
A31: SC | D31: DR2509 | G31: SCT Right Camera Y | H31: =E31&F31&" "&G31 -> SCT Right Camera Y | I31: =IF(OR(LEFT(O31,3)="SGL",LEFT(O31,5)="SGMCS"),"LINEAR","Rotary") -> Rotary | J31: =IF(OR(RIGHT($H31,1)="Z",LEFT(RIGHT($H31,2),1)="Z",LEFT(RIGHT($H31,3),1)="Z"),"Z",IF(OR(RIGHT($H31,1)="X",LEFT(RIGHT($H31,2),1)="X",LEFT(RIGHT($H31,3),1)="X"),"X",IF(OR(RIGHT($H31,1)="Y",LEFT(RIGHT($H31,2),1)="Y",LEFT(RIGHT($H31,3),1)="Y"),"Y","T"))) -> Y | K31: =VLOOKUP($D31,[4]회선정보!B:F,3,FALSE) -> 0 | L31: =VLOOKUP($D31,[4]회선정보!B:F,4,FALSE) -> 9 | M31: =VLOOKUP($D31,[4]회선정보!B:F,5,FALSE) -> MP5-1 | O31: SGM7M-A3A3A21 | P31: =IFERROR(IF($I31="Rotary",LEFT($O31,9),$O31),"") -> SGM7M-A3A | Q31: =IF(MID($N30,5,1)<>"W",VLOOKUP(N31,[4]정격용량!$B$3:$K$633,4,FALSE),"X") -> X | R31: =IF(MID(N30,5,1)<>"W",VLOOKUP(N31,[4]정격용량!$B$3:$K$633,3,FALSE),"X") -> X | S31: =IF(MID(N30,5,1)<>"W",VLOOKUP(N31,[4]정격용량!$B$3:$K$633,6,FALSE),"X") -> X | T31: =IF(MID($N30,5,1)<>"W",S31*$C$85,"X") -> X | U31: =IF(MID($N30,5,1)<>"W",VLOOKUP(N31,[4]정격용량!$B$3:$K$633,9,FALSE),"X") -> X | V31: =IFERROR(IF(J31="Z",VLOOKUP(P31,'[4]SERVO CABLE'!G:AD,8,FALSE),VLOOKUP(P31,'[4]SERVO CABLE'!G:AD,4,FALSE)),"") -> JZSP-CF2M20-□-E | W31: =IFERROR(VLOOKUP(P31,'[4]SERVO CABLE'!G:AD,17,FALSE),"") -> JZSP-C7MP29-□-E | Y31: 2 | Z31: =IF($Y31=1,$R$9,"") | AA31: =IF($Y31=2,$R$9,"") -> 0.25 | AB31: =IF($Y31=3,$R$9,"") | AC31: =IF(MID($N30,5,1)<>"W",((700*700)/$Q31*1.509)/1000,"X") -> X | AD31: =IF($AC31="X","X",IF($AC31<0.1,"X",IF($AC31<0.27,"IRV60",IF($AC31<0.91,"IRV80",IF($AC31<1.1,"IRV100",IF($AC31<1.3,"IRV120",IF($AC31<1.6,"IRV150",IF($AC31<2.2,"IRV200",IF($AC31<2.7,"IRV300",IF($AC31<4.3,"IRV400",IF($AC31<6.8,"IRV500","X"))))))))))) -> X
A32: SC | D32: DR250A | G32: SCT Left Camera Z | H32: =E32&F32&" "&G32 -> SCT Left Camera Z | I32: =IF(OR(LEFT(O32,3)="SGL",LEFT(O32,5)="SGMCS"),"LINEAR","Rotary") -> Rotary | J32: =IF(OR(RIGHT($H32,1)="Z",LEFT(RIGHT($H32,2),1)="Z",LEFT(RIGHT($H32,3),1)="Z"),"Z",IF(OR(RIGHT($H32,1)="X",LEFT(RIGHT($H32,2),1)="X",LEFT(RIGHT($H32,3),1)="X"),"X",IF(OR(RIGHT($H32,1)="Y",LEFT(RIGHT($H32,2),1)="Y",LEFT(RIGHT($H32,3),1)="Y"),"Y","T"))) -> Z | K32: =VLOOKUP($D32,[4]회선정보!B:F,3,FALSE) -> 0 | L32: =VLOOKUP($D32,[4]회선정보!B:F,4,FALSE) -> A | M32: =VLOOKUP($D32,[4]회선정보!B:F,5,FALSE) -> MP5-1 | N32: SGD7W-1R6A20A | O32: SGM7M-A3A3A21 | P32: =IFERROR(IF($I32="Rotary",LEFT($O32,9),$O32),"") -> SGM7M-A3A | Q32: =IF(MID($N31,5,1)<>"W",VLOOKUP(N32,[4]정격용량!$B$3:$K$633,4,FALSE),"X") -> 400 | R32: =IF(MID(N31,5,1)<>"W",VLOOKUP(N32,[4]정격용량!$B$3:$K$633,3,FALSE),"X") -> 0.3 | S32: =IF(MID(N31,5,1)<>"W",VLOOKUP(N32,[4]정격용량!$B$3:$K$633,6,FALSE),"X") -> 2.5 | T32: =IF(MID($N31,5,1)<>"W",S32*$C$85,"X") -> 0.94565217 | U32: =IF(MID($N31,5,1)<>"W",VLOOKUP(N32,[4]정격용량!$B$3:$K$633,9,FALSE),"X") -> 3 | V32: =IFERROR(IF(J32="Z",VLOOKUP(P32,'[4]SERVO CABLE'!G:AD,8,FALSE),VLOOKUP(P32,'[4]SERVO CABLE'!G:AD,4,FALSE)),"") -> JZSP-CF2M23-□-E | W32: =IFERROR(VLOOKUP(P32,'[4]SERVO CABLE'!G:AD,17,FALSE),"") -> JZSP-C7MP29-□-E | Z32: =IF($Y32=1,$R$9,"") | AA32: =IF($Y32=2,$R$9,"") | AB32: =IF($Y32=3,$R$9,"") | AC32: =IF(MID($N31,5,1)<>"W",((700*700)/$Q32*1.509)/1000,"X") -> 1.848525 | AD32: =IF($AC32="X","X",IF($AC32<0.1,"X",IF($AC32<0.27,"IRV60",IF($AC32<0.91,"IRV80",IF($AC32<1.1,"IRV100",IF($AC32<1.3,"IRV120",IF($AC32<1.6,"IRV150",IF($AC32<2.2,"IRV200",IF($AC32<2.7,"IRV300",IF($AC32<4.3,"IRV400",IF($AC32<6.8,"IRV500","X"))))))))))) -> IRV200
A33: SC | D33: DR250B | G33: SCT Right Camera Z | H33: =E33&F33&" "&G33 -> SCT Right Camera Z | I33: =IF(OR(LEFT(O33,3)="SGL",LEFT(O33,5)="SGMCS"),"LINEAR","Rotary") -> Rotary | J33: =IF(OR(RIGHT($H33,1)="Z",LEFT(RIGHT($H33,2),1)="Z",LEFT(RIGHT($H33,3),1)="Z"),"Z",IF(OR(RIGHT($H33,1)="X",LEFT(RIGHT($H33,2),1)="X",LEFT(RIGHT($H33,3),1)="X"),"X",IF(OR(RIGHT($H33,1)="Y",LEFT(RIGHT($H33,2),1)="Y",LEFT(RIGHT($H33,3),1)="Y"),"Y","T"))) -> Z | K33: =VLOOKUP($D33,[4]회선정보!B:F,3,FALSE) -> 0 | L33: =VLOOKUP($D33,[4]회선정보!B:F,4,FALSE) -> B | M33: =VLOOKUP($D33,[4]회선정보!B:F,5,FALSE) -> MP5-1 | O33: SGM7M-A3A3A21 | P33: =IFERROR(IF($I33="Rotary",LEFT($O33,9),$O33),"") -> SGM7M-A3A | Q33: =IF(MID($N32,5,1)<>"W",VLOOKUP(N33,[4]정격용량!$B$3:$K$633,4,FALSE),"X") -> X | R33: =IF(MID(N32,5,1)<>"W",VLOOKUP(N33,[4]정격용량!$B$3:$K$633,3,FALSE),"X") -> X | S33: =IF(MID(N32,5,1)<>"W",VLOOKUP(N33,[4]정격용량!$B$3:$K$633,6,FALSE),"X") -> X | U33: =IF(MID($N32,5,1)<>"W",VLOOKUP(N33,[4]정격용량!$B$3:$K$633,9,FALSE),"X") -> X | V33: =IFERROR(IF(J33="Z",VLOOKUP(P33,'[4]SERVO CABLE'!G:AD,8,FALSE),VLOOKUP(P33,'[4]SERVO CABLE'!G:AD,4,FALSE)),"") -> JZSP-CF2M23-□-E | W33: =IFERROR(VLOOKUP(P33,'[4]SERVO CABLE'!G:AD,17,FALSE),"") -> JZSP-C7MP29-□-E | Y33: 3 | Z33: =IF($Y33=1,$R$9,"") | AA33: =IF($Y33=2,$R$9,"") | AB33: =IF($Y33=3,$R$9,"") -> 0.25 | AC33: =IF(MID($N32,5,1)<>"W",((700*700)/$Q33*1.509)/1000,"X") -> X | AD33: =IF($AC33="X","X",IF($AC33<0.1,"X",IF($AC33<0.27,"IRV60",IF($AC33<0.91,"IRV80",IF($AC33<1.1,"IRV100",IF($AC33<1.3,"IRV120",IF($AC33<1.6,"IRV150",IF($AC33<2.2,"IRV200",IF($AC33<2.7,"IRV300",IF($AC33<4.3,"IRV400",IF($AC33<6.8,"IRV500","X"))))))))))) -> X
A34: SC | D34: DR2603 | G34: SCT Scribe Chuck Y-1 | H34: =E34&F34&" "&G34 -> SCT Scribe Chuck Y-1 | I34: =IF(OR(LEFT(O34,3)="SGL",LEFT(O34,5)="SGMCS"),"LINEAR","Rotary") -> LINEAR | J34: =IF(OR(RIGHT($H34,1)="Z",LEFT(RIGHT($H34,2),1)="Z",LEFT(RIGHT($H34,3),1)="Z"),"Z",IF(OR(RIGHT($H34,1)="X",LEFT(RIGHT($H34,2),1)="X",LEFT(RIGHT($H34,3),1)="X"),"X",IF(OR(RIGHT($H34,1)="Y",LEFT(RIGHT($H34,2),1)="Y",LEFT(RIGHT($H34,3),1)="Y"),"Y","T"))) -> Y | K34: =VLOOKUP($D34,[4]회선정보!B:F,3,FALSE) -> 0 | L34: =VLOOKUP($D34,[4]회선정보!B:F,4,FALSE) -> 3 | M34: =VLOOKUP($D34,[4]회선정보!B:F,5,FALSE) -> MP6-1 | N34: SGD7S-120A20A | O34: SGLFW-50A380BP | P34: =IFERROR(IF($I34="Rotary",LEFT($O34,9),$O34),"") -> SGLFW-50A380BP | Q34: =IF(MID($N33,5,1)<>"W",VLOOKUP(N34,[4]정격용량!$B$3:$K$633,4,FALSE),"X") -> 1500 | R34: =IF(MID(N33,5,1)<>"W",VLOOKUP(N34,[4]정격용량!$B$3:$K$633,3,FALSE),"X") -> 0.25 | S34: =IF(MID(N33,5,1)<>"W",VLOOKUP(N34,[4]정격용량!$B$3:$K$633,6,FALSE),"X") -> 7.3 | T34: =IF(MID($N33,5,1)<>"W",S34*$C$85,"X") -> 2.7613043 | U34: =IF(MID($N33,5,1)<>"W",VLOOKUP(N34,[4]정격용량!$B$3:$K$633,9,FALSE),"X") -> 10 | V34: =IFERROR(IF(J34="Z",VLOOKUP(P34,'[4]SERVO CABLE'!G:AD,8,FALSE),VLOOKUP(P34,'[4]SERVO CABLE'!G:AD,4,FALSE)),"") -> JZSP-CLN21-01-E | W34: =IFERROR(VLOOKUP(P34,'[4]SERVO CABLE'!G:AD,17,FALSE),"") -> JZSP-CLP70-□-ER | Z34: =IF($Y34=1,$R$9,"") | AA34: =IF($Y34=2,$R$9,"") | AB34: =IF($Y34=3,$R$9,"") | AC34: =IF(MID($N33,5,1)<>"W",((700*700)/$Q34*1.509)/1000,"X") -> 0.49294 | AD34: =IF($AC34="X","X",IF($AC34<0.1,"X",IF($AC34<0.27,"IRV60",IF($AC34<0.91,"IRV80",IF($AC34<1.1,"IRV100",IF($AC34<1.3,"IRV120",IF($AC34<1.6,"IRV150",IF($AC34<2.2,"IRV200",IF($AC34<2.7,"IRV300",IF($AC34<4.3,"IRV400",IF($AC34<6.8,"IRV500","X"))))))))))) -> IRV80
A35: SC | D35: DR2604 | G35: SCT Scribe Chuck Y-2 | H35: =E35&F35&" "&G35 -> SCT Scribe Chuck Y-2 | I35: =IF(OR(LEFT(O35,3)="SGL",LEFT(O35,5)="SGMCS"),"LINEAR","Rotary") -> LINEAR | J35: =IF(OR(RIGHT($H35,1)="Z",LEFT(RIGHT($H35,2),1)="Z",LEFT(RIGHT($H35,3),1)="Z"),"Z",IF(OR(RIGHT($H35,1)="X",LEFT(RIGHT($H35,2),1)="X",LEFT(RIGHT($H35,3),1)="X"),"X",IF(OR(RIGHT($H35,1)="Y",LEFT(RIGHT($H35,2),1)="Y",LEFT(RIGHT($H35,3),1)="Y"),"Y","T"))) -> Y | K35: =VLOOKUP($D35,[4]회선정보!B:F,3,FALSE) -> 0 | L35: =VLOOKUP($D35,[4]회선정보!B:F,4,FALSE) -> 4 | M35: =VLOOKUP($D35,[4]회선정보!B:F,5,FALSE) -> MP6-1 | N35: SGD7S-120A20A | O35: SGLFW-50A380BP | P35: =IFERROR(IF($I35="Rotary",LEFT($O35,9),$O35),"") -> SGLFW-50A380BP | Q35: =IF(MID($N34,5,1)<>"W",VLOOKUP(N35,[4]정격용량!$B$3:$K$633,4,FALSE),"X") -> 1500 | R35: =IF(MID(N34,5,1)<>"W",VLOOKUP(N35,[4]정격용량!$B$3:$K$633,3,FALSE),"X") -> 0.25 | S35: =IF(MID(N34,5,1)<>"W",VLOOKUP(N35,[4]정격용량!$B$3:$K$633,6,FALSE),"X") -> 7.3 | T35: =IF(MID($N34,5,1)<>"W",S35*$C$85,"X") -> 2.7613043 | U35: =IF(MID($N34,5,1)<>"W",VLOOKUP(N35,[4]정격용량!$B$3:$K$633,9,FALSE),"X") -> 10 | V35: =IFERROR(IF(J35="Z",VLOOKUP(P35,'[4]SERVO CABLE'!G:AD,8,FALSE),VLOOKUP(P35,'[4]SERVO CABLE'!G:AD,4,FALSE)),"") -> JZSP-CLN21-01-E | W35: =IFERROR(VLOOKUP(P35,'[4]SERVO CABLE'!G:AD,17,FALSE),"") -> JZSP-CLP70-□-ER | Y35: 1 | Z35: =IF($Y35=1,$R$9,"") -> 0.25 | AA35: =IF($Y35=2,$R$9,"") | AB35: =IF($Y35=3,$R$9,"") | AC35: =IF(MID($N34,5,1)<>"W",((700*700)/$Q35*1.509)/1000,"X") -> 0.49294 | AD35: =IF($AC35="X","X",IF($AC35<0.1,"X",IF($AC35<0.27,"IRV60",IF($AC35<0.91,"IRV80",IF($AC35<1.1,"IRV100",IF($AC35<1.3,"IRV120",IF($AC35<1.6,"IRV150",IF($AC35<2.2,"IRV200",IF($AC35<2.7,"IRV300",IF($AC35<4.3,"IRV400",IF($AC35<6.8,"IRV500","X"))))))))))) -> IRV80
A36: SC | D36: DR2606 | G36: SCT Scribe Chuck1 Z | H36: =E36&F36&" "&G36 -> SCT Scribe Chuck1 Z | I36: =IF(OR(LEFT(O36,3)="SGL",LEFT(O36,5)="SGMCS"),"LINEAR","Rotary") -> Rotary | J36: =IF(OR(RIGHT($H36,1)="Z",LEFT(RIGHT($H36,2),1)="Z",LEFT(RIGHT($H36,3),1)="Z"),"Z",IF(OR(RIGHT($H36,1)="X",LEFT(RIGHT($H36,2),1)="X",LEFT(RIGHT($H36,3),1)="X"),"X",IF(OR(RIGHT($H36,1)="Y",LEFT(RIGHT($H36,2),1)="Y",LEFT(RIGHT($H36,3),1)="Y"),"Y","T"))) -> Z | K36: =VLOOKUP($D36,[4]회선정보!B:F,3,FALSE) -> 0 | L36: =VLOOKUP($D36,[4]회선정보!B:F,4,FALSE) -> 6 | M36: =VLOOKUP($D36,[4]회선정보!B:F,5,FALSE) -> MP6-1 | N36: SGD7W-1R6A20A | O36: SGM7J-A5A7A21 | P36: =IFERROR(IF($I36="Rotary",LEFT($O36,9),$O36),"") -> SGM7J-A5A | Q36: =IF(MID($N35,5,1)<>"W",VLOOKUP(N36,[4]정격용량!$B$3:$K$633,4,FALSE),"X") -> 400 | R36: =IF(MID(N35,5,1)<>"W",VLOOKUP(N36,[4]정격용량!$B$3:$K$633,3,FALSE),"X") -> 0.3 | S36: =IF(MID(N35,5,1)<>"W",VLOOKUP(N36,[4]정격용량!$B$3:$K$633,6,FALSE),"X") -> 2.5 | T36: =IF(MID($N35,5,1)<>"W",S36*$C$85,"X") -> 0.94565217 | U36: =IF(MID($N35,5,1)<>"W",VLOOKUP(N36,[4]정격용량!$B$3:$K$633,9,FALSE),"X") -> 3 | V36: =IFERROR(IF(J36="Z",VLOOKUP(P36,'[4]SERVO CABLE'!G:AD,8,FALSE),VLOOKUP(P36,'[4]SERVO CABLE'!G:AD,4,FALSE)),"") -> JZSP-C7M14F-□-E | W36: =IFERROR(VLOOKUP(P36,'[4]SERVO CABLE'!G:AD,17,FALSE),"") -> JZSP-C7PA2D-□-E | Z36: =IF($Y36=1,$R$9,"") | AA36: =IF($Y36=2,$R$9,"") | AB36: =IF($Y36=3,$R$9,"") | AC36: =IF(MID($N35,5,1)<>"W",((700*700)/$Q36*1.509)/1000,"X") -> 1.848525 | AD36: =IF($AC36="X","X",IF($AC36<0.1,"X",IF($AC36<0.27,"IRV60",IF($AC36<0.91,"IRV80",IF($AC36<1.1,"IRV100",IF($AC36<1.3,"IRV120",IF($AC36<1.6,"IRV150",IF($AC36<2.2,"IRV200",IF($AC36<2.7,"IRV300",IF($AC36<4.3,"IRV400",IF($AC36<6.8,"IRV500","X"))))))))))) -> IRV200
A37: SC | D37: DR2607 | G37: SCT Scribe Chuck2 Z | H37: =E37&F37&" "&G37 -> SCT Scribe Chuck2 Z | I37: =IF(OR(LEFT(O37,3)="SGL",LEFT(O37,5)="SGMCS"),"LINEAR","Rotary") -> Rotary | J37: =IF(OR(RIGHT($H37,1)="Z",LEFT(RIGHT($H37,2),1)="Z",LEFT(RIGHT($H37,3),1)="Z"),"Z",IF(OR(RIGHT($H37,1)="X",LEFT(RIGHT($H37,2),1)="X",LEFT(RIGHT($H37,3),1)="X"),"X",IF(OR(RIGHT($H37,1)="Y",LEFT(RIGHT($H37,2),1)="Y",LEFT(RIGHT($H37,3),1)="Y"),"Y","T"))) -> Z | K37: =VLOOKUP($D37,[4]회선정보!B:F,3,FALSE) -> 0 | L37: =VLOOKUP($D37,[4]회선정보!B:F,4,FALSE) -> 7 | M37: =VLOOKUP($D37,[4]회선정보!B:F,5,FALSE) -> MP6-1 | O37: SGM7J-A5A7A21 | P37: =IFERROR(IF($I37="Rotary",LEFT($O37,9),$O37),"") -> SGM7J-A5A | Q37: =IF(MID($N36,5,1)<>"W",VLOOKUP(N37,[4]정격용량!$B$3:$K$633,4,FALSE),"X") -> X | R37: =IF(MID(N36,5,1)<>"W",VLOOKUP(N37,[4]정격용량!$B$3:$K$633,3,FALSE),"X") -> X | S37: =IF(MID(N36,5,1)<>"W",VLOOKUP(N37,[4]정격용량!$B$3:$K$633,6,FALSE),"X") -> X | T37: =IF(MID($N36,5,1)<>"W",S37*$C$85,"X") -> X | U37: =IF(MID($N36,5,1)<>"W",VLOOKUP(N37,[4]정격용량!$B$3:$K$633,9,FALSE),"X") -> X | V37: =IFERROR(IF(J37="Z",VLOOKUP(P37,'[4]SERVO CABLE'!G:AD,8,FALSE),VLOOKUP(P37,'[4]SERVO CABLE'!G:AD,4,FALSE)),"") -> JZSP-C7M14F-□-E | W37: =IFERROR(VLOOKUP(P37,'[4]SERVO CABLE'!G:AD,17,FALSE),"") -> JZSP-C7PA2D-□-E | Y37: 2 | Z37: =IF($Y37=1,$R$9,"") | AA37: =IF($Y37=2,$R$9,"") -> 0.25 | AB37: =IF($Y37=3,$R$9,"") | AC37: =IF(MID($N36,5,1)<>"W",((700*700)/$Q37*1.509)/1000,"X") -> X | AD37: =IF($AC37="X","X",IF($AC37<0.1,"X",IF($AC37<0.27,"IRV60",IF($AC37<0.91,"IRV80",IF($AC37<1.1,"IRV100",IF($AC37<1.3,"IRV120",IF($AC37<1.6,"IRV150",IF($AC37<2.2,"IRV200",IF($AC37<2.7,"IRV300",IF($AC37<4.3,"IRV400",IF($AC37<6.8,"IRV500","X"))))))))))) -> X
A38: SC | D38: DR2608 | G38: SCT Scribe Chuck3 Z | H38: =E38&F38&" "&G38 -> SCT Scribe Chuck3 Z | I38: =IF(OR(LEFT(O38,3)="SGL",LEFT(O38,5)="SGMCS"),"LINEAR","Rotary") -> Rotary | J38: =IF(OR(RIGHT($H38,1)="Z",LEFT(RIGHT($H38,2),1)="Z",LEFT(RIGHT($H38,3),1)="Z"),"Z",IF(OR(RIGHT($H38,1)="X",LEFT(RIGHT($H38,2),1)="X",LEFT(RIGHT($H38,3),1)="X"),"X",IF(OR(RIGHT($H38,1)="Y",LEFT(RIGHT($H38,2),1)="Y",LEFT(RIGHT($H38,3),1)="Y"),"Y","T"))) -> Z | K38: =VLOOKUP($D38,[4]회선정보!B:F,3,FALSE) -> 0 | L38: =VLOOKUP($D38,[4]회선정보!B:F,4,FALSE) -> 8 | M38: =VLOOKUP($D38,[4]회선정보!B:F,5,FALSE) -> MP6-1 | N38: SGD7W-1R6A20A | O38: SGM7J-A5A7A21 | P38: =IFERROR(IF($I38="Rotary",LEFT($O38,9),$O38),"") -> SGM7J-A5A | Q38: =IF(MID($N37,5,1)<>"W",VLOOKUP(N38,[4]정격용량!$B$3:$K$633,4,FALSE),"X") -> 400 | R38: =IF(MID(N37,5,1)<>"W",VLOOKUP(N38,[4]정격용량!$B$3:$K$633,3,FALSE),"X") -> 0.3 | S38: =IF(MID(N37,5,1)<>"W",VLOOKUP(N38,[4]정격용량!$B$3:$K$633,6,FALSE),"X") -> 2.5 | T38: =IF(MID($N37,5,1)<>"W",S38*$C$85,"X") -> 0.94565217 | U38: =IF(MID($N37,5,1)<>"W",VLOOKUP(N38,[4]정격용량!$B$3:$K$633,9,FALSE),"X") -> 3 | V38: =IFERROR(IF(J38="Z",VLOOKUP(P38,'[4]SERVO CABLE'!G:AD,8,FALSE),VLOOKUP(P38,'[4]SERVO CABLE'!G:AD,4,FALSE)),"") -> JZSP-C7M14F-□-E | W38: =IFERROR(VLOOKUP(P38,'[4]SERVO CABLE'!G:AD,17,FALSE),"") -> JZSP-C7PA2D-□-E | Z38: =IF($Y38=1,$R$9,"") | AA38: =IF($Y38=2,$R$9,"") | AB38: =IF($Y38=3,$R$9,"") | AC38: =IF(MID($N37,5,1)<>"W",((700*700)/$Q38*1.509)/1000,"X") -> 1.848525 | AD38: =IF($AC38="X","X",IF($AC38<0.1,"X",IF($AC38<0.27,"IRV60",IF($AC38<0.91,"IRV80",IF($AC38<1.1,"IRV100",IF($AC38<1.3,"IRV120",IF($AC38<1.6,"IRV150",IF($AC38<2.2,"IRV200",IF($AC38<2.7,"IRV300",IF($AC38<4.3,"IRV400",IF($AC38<6.8,"IRV500","X"))))))))))) -> IRV200
A39: SC | D39: DR2609 | G39: SCT Scribe Chuck4 Z | H39: =E39&F39&" "&G39 -> SCT Scribe Chuck4 Z | I39: =IF(OR(LEFT(O39,3)="SGL",LEFT(O39,5)="SGMCS"),"LINEAR","Rotary") -> Rotary | J39: =IF(OR(RIGHT($H39,1)="Z",LEFT(RIGHT($H39,2),1)="Z",LEFT(RIGHT($H39,3),1)="Z"),"Z",IF(OR(RIGHT($H39,1)="X",LEFT(RIGHT($H39,2),1)="X",LEFT(RIGHT($H39,3),1)="X"),"X",IF(OR(RIGHT($H39,1)="Y",LEFT(RIGHT($H39,2),1)="Y",LEFT(RIGHT($H39,3),1)="Y"),"Y","T"))) -> Z | K39: =VLOOKUP($D39,[4]회선정보!B:F,3,FALSE) -> 0 | L39: =VLOOKUP($D39,[4]회선정보!B:F,4,FALSE) -> 9 | M39: =VLOOKUP($D39,[4]회선정보!B:F,5,FALSE) -> MP6-1 | O39: SGM7J-A5A7A21 | P39: =IFERROR(IF($I39="Rotary",LEFT($O39,9),$O39),"") -> SGM7J-A5A | Q39: =IF(MID($N38,5,1)<>"W",VLOOKUP(N39,[4]정격용량!$B$3:$K$633,4,FALSE),"X") -> X | R39: =IF(MID(N38,5,1)<>"W",VLOOKUP(N39,[4]정격용량!$B$3:$K$633,3,FALSE),"X") -> X | S39: =IF(MID(N38,5,1)<>"W",VLOOKUP(N39,[4]정격용량!$B$3:$K$633,6,FALSE),"X") -> X | T39: =IF(MID($N38,5,1)<>"W",S39*$C$85,"X") -> X | U39: =IF(MID($N38,5,1)<>"W",VLOOKUP(N39,[4]정격용량!$B$3:$K$633,9,FALSE),"X") -> X | V39: =IFERROR(IF(J39="Z",VLOOKUP(P39,'[4]SERVO CABLE'!G:AD,8,FALSE),VLOOKUP(P39,'[4]SERVO CABLE'!G:AD,4,FALSE)),"") -> JZSP-C7M14F-□-E | W39: =IFERROR(VLOOKUP(P39,'[4]SERVO CABLE'!G:AD,17,FALSE),"") -> JZSP-C7PA2D-□-E | Y39: 3 | Z39: =IF($Y39=1,$R$9,"") | AA39: =IF($Y39=2,$R$9,"") | AB39: =IF($Y39=3,$R$9,"") -> 0.25 | AC39: =IF(MID($N38,5,1)<>"W",((700*700)/$Q39*1.509)/1000,"X") -> X | AD39: =IF($AC39="X","X",IF($AC39<0.1,"X",IF($AC39<0.27,"IRV60",IF($AC39<0.91,"IRV80",IF($AC39<1.1,"IRV100",IF($AC39<1.3,"IRV120",IF($AC39<1.6,"IRV150",IF($AC39<2.2,"IRV200",IF($AC39<2.7,"IRV300",IF($AC39<4.3,"IRV400",IF($AC39<6.8,"IRV500","X"))))))))))) -> X
A40: SC | D40: DR260A | G40: SCT Scribe Chuck5 Z | H40: =E40&F40&" "&G40 -> SCT Scribe Chuck5 Z | I40: =IF(OR(LEFT(O40,3)="SGL",LEFT(O40,5)="SGMCS"),"LINEAR","Rotary") -> Rotary | J40: =IF(OR(RIGHT($H40,1)="Z",LEFT(RIGHT($H40,2),1)="Z",LEFT(RIGHT($H40,3),1)="Z"),"Z",IF(OR(RIGHT($H40,1)="X",LEFT(RIGHT($H40,2),1)="X",LEFT(RIGHT($H40,3),1)="X"),"X",IF(OR(RIGHT($H40,1)="Y",LEFT(RIGHT($H40,2),1)="Y",LEFT(RIGHT($H40,3),1)="Y"),"Y","T"))) -> Z | K40: =VLOOKUP($D40,[4]회선정보!B:F,3,FALSE) -> 0 | L40: =VLOOKUP($D40,[4]회선정보!B:F,4,FALSE) -> A | M40: =VLOOKUP($D40,[4]회선정보!B:F,5,FALSE) -> MP6-1 | N40: SGD7W-1R6A20A | O40: SGM7J-A5A7A21 | P40: =IFERROR(IF($I40="Rotary",LEFT($O40,9),$O40),"") -> SGM7J-A5A | Q40: =IF(MID($N39,5,1)<>"W",VLOOKUP(N40,[4]정격용량!$B$3:$K$633,4,FALSE),"X") -> 400 | R40: =IF(MID(N39,5,1)<>"W",VLOOKUP(N40,[4]정격용량!$B$3:$K$633,3,FALSE),"X") -> 0.3 | S40: =IF(MID(N39,5,1)<>"W",VLOOKUP(N40,[4]정격용량!$B$3:$K$633,6,FALSE),"X") -> 2.5 | T40: =IF(MID($N39,5,1)<>"W",S40*$C$85,"X") -> 0.94565217 | U40: =IF(MID($N39,5,1)<>"W",VLOOKUP(N40,[4]정격용량!$B$3:$K$633,9,FALSE),"X") -> 3 | V40: =IFERROR(IF(J40="Z",VLOOKUP(P40,'[4]SERVO CABLE'!G:AD,8,FALSE),VLOOKUP(P40,'[4]SERVO CABLE'!G:AD,4,FALSE)),"") -> JZSP-C7M14F-□-E | W40: =IFERROR(VLOOKUP(P40,'[4]SERVO CABLE'!G:AD,17,FALSE),"") -> JZSP-C7PA2D-□-E | Z40: =IF($Y40=1,$R$9,"") | AA40: =IF($Y40=2,$R$9,"") | AB40: =IF($Y40=3,$R$9,"") | AC40: =IF(MID($N39,5,1)<>"W",((700*700)/$Q40*1.509)/1000,"X") -> 1.848525 | AD40: =IF($AC40="X","X",IF($AC40<0.1,"X",IF($AC40<0.27,"IRV60",IF($AC40<0.91,"IRV80",IF($AC40<1.1,"IRV100",IF($AC40<1.3,"IRV120",IF($AC40<1.6,"IRV150",IF($AC40<2.2,"IRV200",IF($AC40<2.7,"IRV300",IF($AC40<4.3,"IRV400",IF($AC40<6.8,"IRV500","X"))))))))))) -> IRV200
